[IN√çCIO] 27/07/2025 13:50:29,07 
[INFO] Abrindo Chrome com WhatsApp... 
[INFO] Aguardando 20 segundos para carregamento do WhatsApp... 
[INFO] Executando enviar_todos.py... 
Traceback (most recent call last):
  File "C:\IMPAR\enviar_whatsapp.py", line 1, in <module>
    import pandas as pd
  File "C:\Users\ramos\AppData\Local\Programs\Python\Python313\Lib\site-packages\pandas\__init__.py", line 61, in <module>
    from pandas.core.api import (
    ...<62 lines>...
    )
  File "C:\Users\ramos\AppData\Local\Programs\Python\Python313\Lib\site-packages\pandas\core\api.py", line 1, in <module>
    from pandas._libs import (
    ...<4 lines>...
    )
  File "C:\Users\ramos\AppData\Local\Programs\Python\Python313\Lib\site-packages\pandas\_libs\__init__.py", line 18, in <module>
    from pandas._libs.interval import Interval
  File "pandas/_libs/interval.pyx", line 1, in init pandas._libs.interval
  File "pandas/_libs/hashtable.pyx", line 1, in init pandas._libs.hashtable
  File "pandas/_libs/missing.pyx", line 1, in init pandas._libs.missing
  File "C:\Users\ramos\AppData\Local\Programs\Python\Python313\Lib\site-packages\pandas\_libs\tslibs\__init__.py", line 68, in <module>
    from pandas._libs.tslibs.period import (
    ...<2 lines>...
    )
ImportError: DLL load failed while importing period: O arquivo de paginaÁ„o È muito pequeno para que esta operaÁ„o seja concluÌda.
[13:57:04] Iniciando envio pela planilha...
[13:57] Avaliando envio para M„e (+5548999181410)...
     [HORA] Agora: 27/07/2025 13:57 | Agendado: 27/07/2025 13:48
[13:57] Enviando mensagem para M„e (+5548999181410)...
Traceback (most recent call last):
  File "C:\IMPAR\enviar_whatsapp.py", line 67, in main
    subprocess.run(["python", CAMINHO_SCRIPT_ENVIO, telefone, mensagem], check=True)
    ~~~~~~~~~~~~~~^^^^^^^^^^^^^^^^^^^^^^^^^^^^^^^^^^^^^^^^^^^^^^^^^^^^^^^^^^^^^^^^^^
  File "C:\Users\ramos\AppData\Local\Programs\Python\Python313\Lib\subprocess.py", line 577, in run
    raise CalledProcessError(retcode, process.args,
                             output=stdout, stderr=stderr)
subprocess.CalledProcessError: Command '['python', 'C:/IMPAR/enviar_whatsapp.py', '+5548999181410', 'Feliz anivers·rio, M„e! \U0001f389']' returned non-zero exit status 1.

During handling of the above exception, another exception occurred:

Traceback (most recent call last):
  File "C:\IMPAR\enviar_whatsapp.py", line 78, in <module>
    main()
    ~~~~^^
  File "C:\IMPAR\enviar_whatsapp.py", line 71, in main
    print(f"[ERRO] Erro ao enviar para {telefone}: {e}")
    ~~~~~^^^^^^^^^^^^^^^^^^^^^^^^^^^^^^^^^^^^^^^^^^^^^^^
  File "C:\Users\ramos\AppData\Local\Programs\Python\Python313\Lib\encodings\cp1252.py", line 19, in encode
    return codecs.charmap_encode(input,self.errors,encoding_table)[0]
           ~~~~~~~~~~~~~~~~~~~~~^^^^^^^^^^^^^^^^^^^^^^^^^^^^^^^^^^
UnicodeEncodeError: 'charmap' codec can't encode character '\U0001f389' in position 137: character maps to <undefined>
[13:56:52] Iniciando envio pela planilha...
[13:56] Avaliando envio para M„e (+5548999181410)...
     [HORA] Agora: 27/07/2025 13:56 | Agendado: 27/07/2025 13:48
[13:56] Enviando mensagem para M„e (+5548999181410)...
Traceback (most recent call last):
  File "C:\IMPAR\enviar_whatsapp.py", line 67, in main
    subprocess.run(["python", CAMINHO_SCRIPT_ENVIO, telefone, mensagem], check=True)
    ~~~~~~~~~~~~~~^^^^^^^^^^^^^^^^^^^^^^^^^^^^^^^^^^^^^^^^^^^^^^^^^^^^^^^^^^^^^^^^^^
  File "C:\Users\ramos\AppData\Local\Programs\Python\Python313\Lib\subprocess.py", line 577, in run
    raise CalledProcessError(retcode, process.args,
                             output=stdout, stderr=stderr)
subprocess.CalledProcessError: Command '['python', 'C:/IMPAR/enviar_whatsapp.py', '+5548999181410', 'Feliz anivers·rio, M„e! \U0001f389']' returned non-zero exit status 1.

During handling of the above exception, another exception occurred:

Traceback (most recent call last):
  File "C:\IMPAR\enviar_whatsapp.py", line 78, in <module>
    main()
    ~~~~^^
  File "C:\IMPAR\enviar_whatsapp.py", line 71, in main
    print(f"[ERRO] Erro ao enviar para {telefone}: {e}")
    ~~~~~^^^^^^^^^^^^^^^^^^^^^^^^^^^^^^^^^^^^^^^^^^^^^^^
  File "C:\Users\ramos\AppData\Local\Programs\Python\Python313\Lib\encodings\cp1252.py", line 19, in encode
    return codecs.charmap_encode(input,self.errors,encoding_table)[0]
           ~~~~~~~~~~~~~~~~~~~~~^^^^^^^^^^^^^^^^^^^^^^^^^^^^^^^^^^
UnicodeEncodeError: 'charmap' codec can't encode character '\U0001f389' in position 137: character maps to <undefined>
[13:56:49] Iniciando envio pela planilha...
[13:56] Avaliando envio para M„e (+5548999181410)...
     [HORA] Agora: 27/07/2025 13:56 | Agendado: 27/07/2025 13:48
[13:56] Enviando mensagem para M„e (+5548999181410)...
Traceback (most recent call last):
  File "C:\IMPAR\enviar_whatsapp.py", line 67, in main
    subprocess.run(["python", CAMINHO_SCRIPT_ENVIO, telefone, mensagem], check=True)
    ~~~~~~~~~~~~~~^^^^^^^^^^^^^^^^^^^^^^^^^^^^^^^^^^^^^^^^^^^^^^^^^^^^^^^^^^^^^^^^^^
  File "C:\Users\ramos\AppData\Local\Programs\Python\Python313\Lib\subprocess.py", line 577, in run
    raise CalledProcessError(retcode, process.args,
                             output=stdout, stderr=stderr)
subprocess.CalledProcessError: Command '['python', 'C:/IMPAR/enviar_whatsapp.py', '+5548999181410', 'Feliz anivers·rio, M„e! \U0001f389']' returned non-zero exit status 1.

During handling of the above exception, another exception occurred:

Traceback (most recent call last):
  File "C:\IMPAR\enviar_whatsapp.py", line 78, in <module>
    main()
    ~~~~^^
  File "C:\IMPAR\enviar_whatsapp.py", line 71, in main
    print(f"[ERRO] Erro ao enviar para {telefone}: {e}")
    ~~~~~^^^^^^^^^^^^^^^^^^^^^^^^^^^^^^^^^^^^^^^^^^^^^^^
  File "C:\Users\ramos\AppData\Local\Programs\Python\Python313\Lib\encodings\cp1252.py", line 19, in encode
    return codecs.charmap_encode(input,self.errors,encoding_table)[0]
           ~~~~~~~~~~~~~~~~~~~~~^^^^^^^^^^^^^^^^^^^^^^^^^^^^^^^^^^
UnicodeEncodeError: 'charmap' codec can't encode character '\U0001f389' in position 137: character maps to <undefined>
[13:56:13] Iniciando envio pela planilha...
[13:56] Avaliando envio para M„e (+5548999181410)...
     [HORA] Agora: 27/07/2025 13:56 | Agendado: 27/07/2025 13:48
[13:56] Enviando mensagem para M„e (+5548999181410)...
Traceback (most recent call last):
  File "C:\IMPAR\enviar_whatsapp.py", line 67, in main
    subprocess.run(["python", CAMINHO_SCRIPT_ENVIO, telefone, mensagem], check=True)
    ~~~~~~~~~~~~~~^^^^^^^^^^^^^^^^^^^^^^^^^^^^^^^^^^^^^^^^^^^^^^^^^^^^^^^^^^^^^^^^^^
  File "C:\Users\ramos\AppData\Local\Programs\Python\Python313\Lib\subprocess.py", line 577, in run
    raise CalledProcessError(retcode, process.args,
                             output=stdout, stderr=stderr)
subprocess.CalledProcessError: Command '['python', 'C:/IMPAR/enviar_whatsapp.py', '+5548999181410', 'Feliz anivers·rio, M„e! \U0001f389']' returned non-zero exit status 1.

During handling of the above exception, another exception occurred:

Traceback (most recent call last):
  File "C:\IMPAR\enviar_whatsapp.py", line 78, in <module>
    main()
    ~~~~^^
  File "C:\IMPAR\enviar_whatsapp.py", line 71, in main
    print(f"[ERRO] Erro ao enviar para {telefone}: {e}")
    ~~~~~^^^^^^^^^^^^^^^^^^^^^^^^^^^^^^^^^^^^^^^^^^^^^^^
  File "C:\Users\ramos\AppData\Local\Programs\Python\Python313\Lib\encodings\cp1252.py", line 19, in encode
    return codecs.charmap_encode(input,self.errors,encoding_table)[0]
           ~~~~~~~~~~~~~~~~~~~~~^^^^^^^^^^^^^^^^^^^^^^^^^^^^^^^^^^
UnicodeEncodeError: 'charmap' codec can't encode character '\U0001f389' in position 137: character maps to <undefined>
[13:55:48] Iniciando envio pela planilha...
[13:55] Avaliando envio para M„e (+5548999181410)...
     [HORA] Agora: 27/07/2025 13:55 | Agendado: 27/07/2025 13:48
[13:55] Enviando mensagem para M„e (+5548999181410)...
Traceback (most recent call last):
  File "C:\IMPAR\enviar_whatsapp.py", line 67, in main
    subprocess.run(["python", CAMINHO_SCRIPT_ENVIO, telefone, mensagem], check=True)
    ~~~~~~~~~~~~~~^^^^^^^^^^^^^^^^^^^^^^^^^^^^^^^^^^^^^^^^^^^^^^^^^^^^^^^^^^^^^^^^^^
  File "C:\Users\ramos\AppData\Local\Programs\Python\Python313\Lib\subprocess.py", line 577, in run
    raise CalledProcessError(retcode, process.args,
                             output=stdout, stderr=stderr)
subprocess.CalledProcessError: Command '['python', 'C:/IMPAR/enviar_whatsapp.py', '+5548999181410', 'Feliz anivers·rio, M„e! \U0001f389']' returned non-zero exit status 1.

During handling of the above exception, another exception occurred:

Traceback (most recent call last):
  File "C:\IMPAR\enviar_whatsapp.py", line 78, in <module>
    main()
    ~~~~^^
  File "C:\IMPAR\enviar_whatsapp.py", line 71, in main
    print(f"[ERRO] Erro ao enviar para {telefone}: {e}")
    ~~~~~^^^^^^^^^^^^^^^^^^^^^^^^^^^^^^^^^^^^^^^^^^^^^^^
  File "C:\Users\ramos\AppData\Local\Programs\Python\Python313\Lib\encodings\cp1252.py", line 19, in encode
    return codecs.charmap_encode(input,self.errors,encoding_table)[0]
           ~~~~~~~~~~~~~~~~~~~~~^^^^^^^^^^^^^^^^^^^^^^^^^^^^^^^^^^
UnicodeEncodeError: 'charmap' codec can't encode character '\U0001f389' in position 137: character maps to <undefined>
[13:55:37] Iniciando envio pela planilha...
[13:55] Avaliando envio para M„e (+5548999181410)...
     [HORA] Agora: 27/07/2025 13:55 | Agendado: 27/07/2025 13:48
[13:55] Enviando mensagem para M„e (+5548999181410)...
Traceback (most recent call last):
  File "C:\IMPAR\enviar_whatsapp.py", line 67, in main
    subprocess.run(["python", CAMINHO_SCRIPT_ENVIO, telefone, mensagem], check=True)
    ~~~~~~~~~~~~~~^^^^^^^^^^^^^^^^^^^^^^^^^^^^^^^^^^^^^^^^^^^^^^^^^^^^^^^^^^^^^^^^^^
  File "C:\Users\ramos\AppData\Local\Programs\Python\Python313\Lib\subprocess.py", line 577, in run
    raise CalledProcessError(retcode, process.args,
                             output=stdout, stderr=stderr)
subprocess.CalledProcessError: Command '['python', 'C:/IMPAR/enviar_whatsapp.py', '+5548999181410', 'Feliz anivers·rio, M„e! \U0001f389']' returned non-zero exit status 1.

During handling of the above exception, another exception occurred:

Traceback (most recent call last):
  File "C:\IMPAR\enviar_whatsapp.py", line 78, in <module>
    main()
    ~~~~^^
  File "C:\IMPAR\enviar_whatsapp.py", line 71, in main
    print(f"[ERRO] Erro ao enviar para {telefone}: {e}")
    ~~~~~^^^^^^^^^^^^^^^^^^^^^^^^^^^^^^^^^^^^^^^^^^^^^^^
  File "C:\Users\ramos\AppData\Local\Programs\Python\Python313\Lib\encodings\cp1252.py", line 19, in encode
    return codecs.charmap_encode(input,self.errors,encoding_table)[0]
           ~~~~~~~~~~~~~~~~~~~~~^^^^^^^^^^^^^^^^^^^^^^^^^^^^^^^^^^
UnicodeEncodeError: 'charmap' codec can't encode character '\U0001f389' in position 137: character maps to <undefined>
[13:55:30] Iniciando envio pela planilha...
[13:55] Avaliando envio para M„e (+5548999181410)...
     [HORA] Agora: 27/07/2025 13:55 | Agendado: 27/07/2025 13:48
[13:55] Enviando mensagem para M„e (+5548999181410)...
Traceback (most recent call last):
  File "C:\IMPAR\enviar_whatsapp.py", line 67, in main
    subprocess.run(["python", CAMINHO_SCRIPT_ENVIO, telefone, mensagem], check=True)
    ~~~~~~~~~~~~~~^^^^^^^^^^^^^^^^^^^^^^^^^^^^^^^^^^^^^^^^^^^^^^^^^^^^^^^^^^^^^^^^^^
  File "C:\Users\ramos\AppData\Local\Programs\Python\Python313\Lib\subprocess.py", line 577, in run
    raise CalledProcessError(retcode, process.args,
                             output=stdout, stderr=stderr)
subprocess.CalledProcessError: Command '['python', 'C:/IMPAR/enviar_whatsapp.py', '+5548999181410', 'Feliz anivers·rio, M„e! \U0001f389']' returned non-zero exit status 1.

During handling of the above exception, another exception occurred:

Traceback (most recent call last):
  File "C:\IMPAR\enviar_whatsapp.py", line 78, in <module>
    main()
    ~~~~^^
  File "C:\IMPAR\enviar_whatsapp.py", line 71, in main
    print(f"[ERRO] Erro ao enviar para {telefone}: {e}")
    ~~~~~^^^^^^^^^^^^^^^^^^^^^^^^^^^^^^^^^^^^^^^^^^^^^^^
  File "C:\Users\ramos\AppData\Local\Programs\Python\Python313\Lib\encodings\cp1252.py", line 19, in encode
    return codecs.charmap_encode(input,self.errors,encoding_table)[0]
           ~~~~~~~~~~~~~~~~~~~~~^^^^^^^^^^^^^^^^^^^^^^^^^^^^^^^^^^
UnicodeEncodeError: 'charmap' codec can't encode character '\U0001f389' in position 137: character maps to <undefined>
[13:55:24] Iniciando envio pela planilha...
[13:55] Avaliando envio para M„e (+5548999181410)...
     [HORA] Agora: 27/07/2025 13:55 | Agendado: 27/07/2025 13:48
[13:55] Enviando mensagem para M„e (+5548999181410)...
Traceback (most recent call last):
  File "C:\IMPAR\enviar_whatsapp.py", line 67, in main
    subprocess.run(["python", CAMINHO_SCRIPT_ENVIO, telefone, mensagem], check=True)
    ~~~~~~~~~~~~~~^^^^^^^^^^^^^^^^^^^^^^^^^^^^^^^^^^^^^^^^^^^^^^^^^^^^^^^^^^^^^^^^^^
  File "C:\Users\ramos\AppData\Local\Programs\Python\Python313\Lib\subprocess.py", line 577, in run
    raise CalledProcessError(retcode, process.args,
                             output=stdout, stderr=stderr)
subprocess.CalledProcessError: Command '['python', 'C:/IMPAR/enviar_whatsapp.py', '+5548999181410', 'Feliz anivers·rio, M„e! \U0001f389']' returned non-zero exit status 1.

During handling of the above exception, another exception occurred:

Traceback (most recent call last):
  File "C:\IMPAR\enviar_whatsapp.py", line 78, in <module>
    main()
    ~~~~^^
  File "C:\IMPAR\enviar_whatsapp.py", line 71, in main
    print(f"[ERRO] Erro ao enviar para {telefone}: {e}")
    ~~~~~^^^^^^^^^^^^^^^^^^^^^^^^^^^^^^^^^^^^^^^^^^^^^^^
  File "C:\Users\ramos\AppData\Local\Programs\Python\Python313\Lib\encodings\cp1252.py", line 19, in encode
    return codecs.charmap_encode(input,self.errors,encoding_table)[0]
           ~~~~~~~~~~~~~~~~~~~~~^^^^^^^^^^^^^^^^^^^^^^^^^^^^^^^^^^
UnicodeEncodeError: 'charmap' codec can't encode character '\U0001f389' in position 137: character maps to <undefined>
[13:55:21] Iniciando envio pela planilha...
[13:55] Avaliando envio para M„e (+5548999181410)...
     [HORA] Agora: 27/07/2025 13:55 | Agendado: 27/07/2025 13:48
[13:55] Enviando mensagem para M„e (+5548999181410)...
Traceback (most recent call last):
  File "C:\IMPAR\enviar_whatsapp.py", line 67, in main
    subprocess.run(["python", CAMINHO_SCRIPT_ENVIO, telefone, mensagem], check=True)
    ~~~~~~~~~~~~~~^^^^^^^^^^^^^^^^^^^^^^^^^^^^^^^^^^^^^^^^^^^^^^^^^^^^^^^^^^^^^^^^^^
  File "C:\Users\ramos\AppData\Local\Programs\Python\Python313\Lib\subprocess.py", line 577, in run
    raise CalledProcessError(retcode, process.args,
                             output=stdout, stderr=stderr)
subprocess.CalledProcessError: Command '['python', 'C:/IMPAR/enviar_whatsapp.py', '+5548999181410', 'Feliz anivers·rio, M„e! \U0001f389']' returned non-zero exit status 1.

During handling of the above exception, another exception occurred:

Traceback (most recent call last):
  File "C:\IMPAR\enviar_whatsapp.py", line 78, in <module>
    main()
    ~~~~^^
  File "C:\IMPAR\enviar_whatsapp.py", line 71, in main
    print(f"[ERRO] Erro ao enviar para {telefone}: {e}")
    ~~~~~^^^^^^^^^^^^^^^^^^^^^^^^^^^^^^^^^^^^^^^^^^^^^^^
  File "C:\Users\ramos\AppData\Local\Programs\Python\Python313\Lib\encodings\cp1252.py", line 19, in encode
    return codecs.charmap_encode(input,self.errors,encoding_table)[0]
           ~~~~~~~~~~~~~~~~~~~~~^^^^^^^^^^^^^^^^^^^^^^^^^^^^^^^^^^
UnicodeEncodeError: 'charmap' codec can't encode character '\U0001f389' in position 137: character maps to <undefined>
[13:55:12] Iniciando envio pela planilha...
[13:55] Avaliando envio para M„e (+5548999181410)...
     [HORA] Agora: 27/07/2025 13:55 | Agendado: 27/07/2025 13:48
[13:55] Enviando mensagem para M„e (+5548999181410)...
Traceback (most recent call last):
  File "C:\IMPAR\enviar_whatsapp.py", line 67, in main
    subprocess.run(["python", CAMINHO_SCRIPT_ENVIO, telefone, mensagem], check=True)
    ~~~~~~~~~~~~~~^^^^^^^^^^^^^^^^^^^^^^^^^^^^^^^^^^^^^^^^^^^^^^^^^^^^^^^^^^^^^^^^^^
  File "C:\Users\ramos\AppData\Local\Programs\Python\Python313\Lib\subprocess.py", line 577, in run
    raise CalledProcessError(retcode, process.args,
                             output=stdout, stderr=stderr)
subprocess.CalledProcessError: Command '['python', 'C:/IMPAR/enviar_whatsapp.py', '+5548999181410', 'Feliz anivers·rio, M„e! \U0001f389']' returned non-zero exit status 1.

During handling of the above exception, another exception occurred:

Traceback (most recent call last):
  File "C:\IMPAR\enviar_whatsapp.py", line 78, in <module>
    main()
    ~~~~^^
  File "C:\IMPAR\enviar_whatsapp.py", line 71, in main
    print(f"[ERRO] Erro ao enviar para {telefone}: {e}")
    ~~~~~^^^^^^^^^^^^^^^^^^^^^^^^^^^^^^^^^^^^^^^^^^^^^^^
  File "C:\Users\ramos\AppData\Local\Programs\Python\Python313\Lib\encodings\cp1252.py", line 19, in encode
    return codecs.charmap_encode(input,self.errors,encoding_table)[0]
           ~~~~~~~~~~~~~~~~~~~~~^^^^^^^^^^^^^^^^^^^^^^^^^^^^^^^^^^
UnicodeEncodeError: 'charmap' codec can't encode character '\U0001f389' in position 137: character maps to <undefined>
[13:55:04] Iniciando envio pela planilha...
[13:55] Avaliando envio para M„e (+5548999181410)...
     [HORA] Agora: 27/07/2025 13:55 | Agendado: 27/07/2025 13:48
[13:55] Enviando mensagem para M„e (+5548999181410)...
Traceback (most recent call last):
  File "C:\IMPAR\enviar_whatsapp.py", line 67, in main
    subprocess.run(["python", CAMINHO_SCRIPT_ENVIO, telefone, mensagem], check=True)
    ~~~~~~~~~~~~~~^^^^^^^^^^^^^^^^^^^^^^^^^^^^^^^^^^^^^^^^^^^^^^^^^^^^^^^^^^^^^^^^^^
  File "C:\Users\ramos\AppData\Local\Programs\Python\Python313\Lib\subprocess.py", line 577, in run
    raise CalledProcessError(retcode, process.args,
                             output=stdout, stderr=stderr)
subprocess.CalledProcessError: Command '['python', 'C:/IMPAR/enviar_whatsapp.py', '+5548999181410', 'Feliz anivers·rio, M„e! \U0001f389']' returned non-zero exit status 1.

During handling of the above exception, another exception occurred:

Traceback (most recent call last):
  File "C:\IMPAR\enviar_whatsapp.py", line 78, in <module>
    main()
    ~~~~^^
  File "C:\IMPAR\enviar_whatsapp.py", line 71, in main
    print(f"[ERRO] Erro ao enviar para {telefone}: {e}")
    ~~~~~^^^^^^^^^^^^^^^^^^^^^^^^^^^^^^^^^^^^^^^^^^^^^^^
  File "C:\Users\ramos\AppData\Local\Programs\Python\Python313\Lib\encodings\cp1252.py", line 19, in encode
    return codecs.charmap_encode(input,self.errors,encoding_table)[0]
           ~~~~~~~~~~~~~~~~~~~~~^^^^^^^^^^^^^^^^^^^^^^^^^^^^^^^^^^
UnicodeEncodeError: 'charmap' codec can't encode character '\U0001f389' in position 137: character maps to <undefined>
[13:54:48] Iniciando envio pela planilha...
[13:54] Avaliando envio para M„e (+5548999181410)...
     [HORA] Agora: 27/07/2025 13:54 | Agendado: 27/07/2025 13:48
[13:54] Enviando mensagem para M„e (+5548999181410)...
Traceback (most recent call last):
  File "C:\IMPAR\enviar_whatsapp.py", line 67, in main
    subprocess.run(["python", CAMINHO_SCRIPT_ENVIO, telefone, mensagem], check=True)
    ~~~~~~~~~~~~~~^^^^^^^^^^^^^^^^^^^^^^^^^^^^^^^^^^^^^^^^^^^^^^^^^^^^^^^^^^^^^^^^^^
  File "C:\Users\ramos\AppData\Local\Programs\Python\Python313\Lib\subprocess.py", line 577, in run
    raise CalledProcessError(retcode, process.args,
                             output=stdout, stderr=stderr)
subprocess.CalledProcessError: Command '['python', 'C:/IMPAR/enviar_whatsapp.py', '+5548999181410', 'Feliz anivers·rio, M„e! \U0001f389']' returned non-zero exit status 1.

During handling of the above exception, another exception occurred:

Traceback (most recent call last):
  File "C:\IMPAR\enviar_whatsapp.py", line 78, in <module>
    main()
    ~~~~^^
  File "C:\IMPAR\enviar_whatsapp.py", line 71, in main
    print(f"[ERRO] Erro ao enviar para {telefone}: {e}")
    ~~~~~^^^^^^^^^^^^^^^^^^^^^^^^^^^^^^^^^^^^^^^^^^^^^^^
  File "C:\Users\ramos\AppData\Local\Programs\Python\Python313\Lib\encodings\cp1252.py", line 19, in encode
    return codecs.charmap_encode(input,self.errors,encoding_table)[0]
           ~~~~~~~~~~~~~~~~~~~~~^^^^^^^^^^^^^^^^^^^^^^^^^^^^^^^^^^
UnicodeEncodeError: 'charmap' codec can't encode character '\U0001f389' in position 137: character maps to <undefined>
[13:54:34] Iniciando envio pela planilha...
[13:54] Avaliando envio para M„e (+5548999181410)...
     [HORA] Agora: 27/07/2025 13:54 | Agendado: 27/07/2025 13:48
[13:54] Enviando mensagem para M„e (+5548999181410)...
Traceback (most recent call last):
  File "C:\IMPAR\enviar_whatsapp.py", line 67, in main
    subprocess.run(["python", CAMINHO_SCRIPT_ENVIO, telefone, mensagem], check=True)
    ~~~~~~~~~~~~~~^^^^^^^^^^^^^^^^^^^^^^^^^^^^^^^^^^^^^^^^^^^^^^^^^^^^^^^^^^^^^^^^^^
  File "C:\Users\ramos\AppData\Local\Programs\Python\Python313\Lib\subprocess.py", line 577, in run
    raise CalledProcessError(retcode, process.args,
                             output=stdout, stderr=stderr)
subprocess.CalledProcessError: Command '['python', 'C:/IMPAR/enviar_whatsapp.py', '+5548999181410', 'Feliz anivers·rio, M„e! \U0001f389']' returned non-zero exit status 1.

During handling of the above exception, another exception occurred:

Traceback (most recent call last):
  File "C:\IMPAR\enviar_whatsapp.py", line 78, in <module>
    main()
    ~~~~^^
  File "C:\IMPAR\enviar_whatsapp.py", line 71, in main
    print(f"[ERRO] Erro ao enviar para {telefone}: {e}")
    ~~~~~^^^^^^^^^^^^^^^^^^^^^^^^^^^^^^^^^^^^^^^^^^^^^^^
  File "C:\Users\ramos\AppData\Local\Programs\Python\Python313\Lib\encodings\cp1252.py", line 19, in encode
    return codecs.charmap_encode(input,self.errors,encoding_table)[0]
           ~~~~~~~~~~~~~~~~~~~~~^^^^^^^^^^^^^^^^^^^^^^^^^^^^^^^^^^
UnicodeEncodeError: 'charmap' codec can't encode character '\U0001f389' in position 137: character maps to <undefined>
[13:54:22] Iniciando envio pela planilha...
[13:54] Avaliando envio para M„e (+5548999181410)...
     [HORA] Agora: 27/07/2025 13:54 | Agendado: 27/07/2025 13:48
[13:54] Enviando mensagem para M„e (+5548999181410)...
Traceback (most recent call last):
  File "C:\IMPAR\enviar_whatsapp.py", line 67, in main
    subprocess.run(["python", CAMINHO_SCRIPT_ENVIO, telefone, mensagem], check=True)
    ~~~~~~~~~~~~~~^^^^^^^^^^^^^^^^^^^^^^^^^^^^^^^^^^^^^^^^^^^^^^^^^^^^^^^^^^^^^^^^^^
  File "C:\Users\ramos\AppData\Local\Programs\Python\Python313\Lib\subprocess.py", line 577, in run
    raise CalledProcessError(retcode, process.args,
                             output=stdout, stderr=stderr)
subprocess.CalledProcessError: Command '['python', 'C:/IMPAR/enviar_whatsapp.py', '+5548999181410', 'Feliz anivers·rio, M„e! \U0001f389']' returned non-zero exit status 1.

During handling of the above exception, another exception occurred:

Traceback (most recent call last):
  File "C:\IMPAR\enviar_whatsapp.py", line 78, in <module>
    main()
    ~~~~^^
  File "C:\IMPAR\enviar_whatsapp.py", line 71, in main
    print(f"[ERRO] Erro ao enviar para {telefone}: {e}")
    ~~~~~^^^^^^^^^^^^^^^^^^^^^^^^^^^^^^^^^^^^^^^^^^^^^^^
  File "C:\Users\ramos\AppData\Local\Programs\Python\Python313\Lib\encodings\cp1252.py", line 19, in encode
    return codecs.charmap_encode(input,self.errors,encoding_table)[0]
           ~~~~~~~~~~~~~~~~~~~~~^^^^^^^^^^^^^^^^^^^^^^^^^^^^^^^^^^
UnicodeEncodeError: 'charmap' codec can't encode character '\U0001f389' in position 137: character maps to <undefined>
[13:54:06] Iniciando envio pela planilha...
[13:54] Avaliando envio para M„e (+5548999181410)...
     [HORA] Agora: 27/07/2025 13:54 | Agendado: 27/07/2025 13:48
[13:54] Enviando mensagem para M„e (+5548999181410)...
Traceback (most recent call last):
  File "C:\IMPAR\enviar_whatsapp.py", line 67, in main
    subprocess.run(["python", CAMINHO_SCRIPT_ENVIO, telefone, mensagem], check=True)
    ~~~~~~~~~~~~~~^^^^^^^^^^^^^^^^^^^^^^^^^^^^^^^^^^^^^^^^^^^^^^^^^^^^^^^^^^^^^^^^^^
  File "C:\Users\ramos\AppData\Local\Programs\Python\Python313\Lib\subprocess.py", line 577, in run
    raise CalledProcessError(retcode, process.args,
                             output=stdout, stderr=stderr)
subprocess.CalledProcessError: Command '['python', 'C:/IMPAR/enviar_whatsapp.py', '+5548999181410', 'Feliz anivers·rio, M„e! \U0001f389']' returned non-zero exit status 1.

During handling of the above exception, another exception occurred:

Traceback (most recent call last):
  File "C:\IMPAR\enviar_whatsapp.py", line 78, in <module>
    main()
    ~~~~^^
  File "C:\IMPAR\enviar_whatsapp.py", line 71, in main
    print(f"[ERRO] Erro ao enviar para {telefone}: {e}")
    ~~~~~^^^^^^^^^^^^^^^^^^^^^^^^^^^^^^^^^^^^^^^^^^^^^^^
  File "C:\Users\ramos\AppData\Local\Programs\Python\Python313\Lib\encodings\cp1252.py", line 19, in encode
    return codecs.charmap_encode(input,self.errors,encoding_table)[0]
           ~~~~~~~~~~~~~~~~~~~~~^^^^^^^^^^^^^^^^^^^^^^^^^^^^^^^^^^
UnicodeEncodeError: 'charmap' codec can't encode character '\U0001f389' in position 137: character maps to <undefined>
[13:53:49] Iniciando envio pela planilha...
[13:53] Avaliando envio para M„e (+5548999181410)...
     [HORA] Agora: 27/07/2025 13:53 | Agendado: 27/07/2025 13:48
[13:53] Enviando mensagem para M„e (+5548999181410)...
Traceback (most recent call last):
  File "C:\IMPAR\enviar_whatsapp.py", line 67, in main
    subprocess.run(["python", CAMINHO_SCRIPT_ENVIO, telefone, mensagem], check=True)
    ~~~~~~~~~~~~~~^^^^^^^^^^^^^^^^^^^^^^^^^^^^^^^^^^^^^^^^^^^^^^^^^^^^^^^^^^^^^^^^^^
  File "C:\Users\ramos\AppData\Local\Programs\Python\Python313\Lib\subprocess.py", line 577, in run
    raise CalledProcessError(retcode, process.args,
                             output=stdout, stderr=stderr)
subprocess.CalledProcessError: Command '['python', 'C:/IMPAR/enviar_whatsapp.py', '+5548999181410', 'Feliz anivers·rio, M„e! \U0001f389']' returned non-zero exit status 1.

During handling of the above exception, another exception occurred:

Traceback (most recent call last):
  File "C:\IMPAR\enviar_whatsapp.py", line 78, in <module>
    main()
    ~~~~^^
  File "C:\IMPAR\enviar_whatsapp.py", line 71, in main
    print(f"[ERRO] Erro ao enviar para {telefone}: {e}")
    ~~~~~^^^^^^^^^^^^^^^^^^^^^^^^^^^^^^^^^^^^^^^^^^^^^^^
  File "C:\Users\ramos\AppData\Local\Programs\Python\Python313\Lib\encodings\cp1252.py", line 19, in encode
    return codecs.charmap_encode(input,self.errors,encoding_table)[0]
           ~~~~~~~~~~~~~~~~~~~~~^^^^^^^^^^^^^^^^^^^^^^^^^^^^^^^^^^
UnicodeEncodeError: 'charmap' codec can't encode character '\U0001f389' in position 137: character maps to <undefined>
[13:53:44] Iniciando envio pela planilha...
[13:53] Avaliando envio para M„e (+5548999181410)...
     [HORA] Agora: 27/07/2025 13:53 | Agendado: 27/07/2025 13:48
[13:53] Enviando mensagem para M„e (+5548999181410)...
Traceback (most recent call last):
  File "C:\IMPAR\enviar_whatsapp.py", line 67, in main
    subprocess.run(["python", CAMINHO_SCRIPT_ENVIO, telefone, mensagem], check=True)
    ~~~~~~~~~~~~~~^^^^^^^^^^^^^^^^^^^^^^^^^^^^^^^^^^^^^^^^^^^^^^^^^^^^^^^^^^^^^^^^^^
  File "C:\Users\ramos\AppData\Local\Programs\Python\Python313\Lib\subprocess.py", line 577, in run
    raise CalledProcessError(retcode, process.args,
                             output=stdout, stderr=stderr)
subprocess.CalledProcessError: Command '['python', 'C:/IMPAR/enviar_whatsapp.py', '+5548999181410', 'Feliz anivers·rio, M„e! \U0001f389']' returned non-zero exit status 1.

During handling of the above exception, another exception occurred:

Traceback (most recent call last):
  File "C:\IMPAR\enviar_whatsapp.py", line 78, in <module>
    main()
    ~~~~^^
  File "C:\IMPAR\enviar_whatsapp.py", line 71, in main
    print(f"[ERRO] Erro ao enviar para {telefone}: {e}")
    ~~~~~^^^^^^^^^^^^^^^^^^^^^^^^^^^^^^^^^^^^^^^^^^^^^^^
  File "C:\Users\ramos\AppData\Local\Programs\Python\Python313\Lib\encodings\cp1252.py", line 19, in encode
    return codecs.charmap_encode(input,self.errors,encoding_table)[0]
           ~~~~~~~~~~~~~~~~~~~~~^^^^^^^^^^^^^^^^^^^^^^^^^^^^^^^^^^
UnicodeEncodeError: 'charmap' codec can't encode character '\U0001f389' in position 137: character maps to <undefined>
[13:53:39] Iniciando envio pela planilha...
[13:53] Avaliando envio para M„e (+5548999181410)...
     [HORA] Agora: 27/07/2025 13:53 | Agendado: 27/07/2025 13:48
[13:53] Enviando mensagem para M„e (+5548999181410)...
Traceback (most recent call last):
  File "C:\IMPAR\enviar_whatsapp.py", line 67, in main
    subprocess.run(["python", CAMINHO_SCRIPT_ENVIO, telefone, mensagem], check=True)
    ~~~~~~~~~~~~~~^^^^^^^^^^^^^^^^^^^^^^^^^^^^^^^^^^^^^^^^^^^^^^^^^^^^^^^^^^^^^^^^^^
  File "C:\Users\ramos\AppData\Local\Programs\Python\Python313\Lib\subprocess.py", line 577, in run
    raise CalledProcessError(retcode, process.args,
                             output=stdout, stderr=stderr)
subprocess.CalledProcessError: Command '['python', 'C:/IMPAR/enviar_whatsapp.py', '+5548999181410', 'Feliz anivers·rio, M„e! \U0001f389']' returned non-zero exit status 1.

During handling of the above exception, another exception occurred:

Traceback (most recent call last):
  File "C:\IMPAR\enviar_whatsapp.py", line 78, in <module>
    main()
    ~~~~^^
  File "C:\IMPAR\enviar_whatsapp.py", line 71, in main
    print(f"[ERRO] Erro ao enviar para {telefone}: {e}")
    ~~~~~^^^^^^^^^^^^^^^^^^^^^^^^^^^^^^^^^^^^^^^^^^^^^^^
  File "C:\Users\ramos\AppData\Local\Programs\Python\Python313\Lib\encodings\cp1252.py", line 19, in encode
    return codecs.charmap_encode(input,self.errors,encoding_table)[0]
           ~~~~~~~~~~~~~~~~~~~~~^^^^^^^^^^^^^^^^^^^^^^^^^^^^^^^^^^
UnicodeEncodeError: 'charmap' codec can't encode character '\U0001f389' in position 137: character maps to <undefined>
[13:53:30] Iniciando envio pela planilha...
[13:53] Avaliando envio para M„e (+5548999181410)...
     [HORA] Agora: 27/07/2025 13:53 | Agendado: 27/07/2025 13:48
[13:53] Enviando mensagem para M„e (+5548999181410)...
Traceback (most recent call last):
  File "C:\IMPAR\enviar_whatsapp.py", line 67, in main
    subprocess.run(["python", CAMINHO_SCRIPT_ENVIO, telefone, mensagem], check=True)
    ~~~~~~~~~~~~~~^^^^^^^^^^^^^^^^^^^^^^^^^^^^^^^^^^^^^^^^^^^^^^^^^^^^^^^^^^^^^^^^^^
  File "C:\Users\ramos\AppData\Local\Programs\Python\Python313\Lib\subprocess.py", line 577, in run
    raise CalledProcessError(retcode, process.args,
                             output=stdout, stderr=stderr)
subprocess.CalledProcessError: Command '['python', 'C:/IMPAR/enviar_whatsapp.py', '+5548999181410', 'Feliz anivers·rio, M„e! \U0001f389']' returned non-zero exit status 1.

During handling of the above exception, another exception occurred:

Traceback (most recent call last):
  File "C:\IMPAR\enviar_whatsapp.py", line 78, in <module>
    main()
    ~~~~^^
  File "C:\IMPAR\enviar_whatsapp.py", line 71, in main
    print(f"[ERRO] Erro ao enviar para {telefone}: {e}")
    ~~~~~^^^^^^^^^^^^^^^^^^^^^^^^^^^^^^^^^^^^^^^^^^^^^^^
  File "C:\Users\ramos\AppData\Local\Programs\Python\Python313\Lib\encodings\cp1252.py", line 19, in encode
    return codecs.charmap_encode(input,self.errors,encoding_table)[0]
           ~~~~~~~~~~~~~~~~~~~~~^^^^^^^^^^^^^^^^^^^^^^^^^^^^^^^^^^
UnicodeEncodeError: 'charmap' codec can't encode character '\U0001f389' in position 137: character maps to <undefined>
[13:53:27] Iniciando envio pela planilha...
[13:53] Avaliando envio para M„e (+5548999181410)...
     [HORA] Agora: 27/07/2025 13:53 | Agendado: 27/07/2025 13:48
[13:53] Enviando mensagem para M„e (+5548999181410)...
Traceback (most recent call last):
  File "C:\IMPAR\enviar_whatsapp.py", line 67, in main
    subprocess.run(["python", CAMINHO_SCRIPT_ENVIO, telefone, mensagem], check=True)
    ~~~~~~~~~~~~~~^^^^^^^^^^^^^^^^^^^^^^^^^^^^^^^^^^^^^^^^^^^^^^^^^^^^^^^^^^^^^^^^^^
  File "C:\Users\ramos\AppData\Local\Programs\Python\Python313\Lib\subprocess.py", line 577, in run
    raise CalledProcessError(retcode, process.args,
                             output=stdout, stderr=stderr)
subprocess.CalledProcessError: Command '['python', 'C:/IMPAR/enviar_whatsapp.py', '+5548999181410', 'Feliz anivers·rio, M„e! \U0001f389']' returned non-zero exit status 1.

During handling of the above exception, another exception occurred:

Traceback (most recent call last):
  File "C:\IMPAR\enviar_whatsapp.py", line 78, in <module>
    main()
    ~~~~^^
  File "C:\IMPAR\enviar_whatsapp.py", line 71, in main
    print(f"[ERRO] Erro ao enviar para {telefone}: {e}")
    ~~~~~^^^^^^^^^^^^^^^^^^^^^^^^^^^^^^^^^^^^^^^^^^^^^^^
  File "C:\Users\ramos\AppData\Local\Programs\Python\Python313\Lib\encodings\cp1252.py", line 19, in encode
    return codecs.charmap_encode(input,self.errors,encoding_table)[0]
           ~~~~~~~~~~~~~~~~~~~~~^^^^^^^^^^^^^^^^^^^^^^^^^^^^^^^^^^
UnicodeEncodeError: 'charmap' codec can't encode character '\U0001f389' in position 137: character maps to <undefined>
[13:53:22] Iniciando envio pela planilha...
[13:53] Avaliando envio para M„e (+5548999181410)...
     [HORA] Agora: 27/07/2025 13:53 | Agendado: 27/07/2025 13:48
[13:53] Enviando mensagem para M„e (+5548999181410)...
Traceback (most recent call last):
  File "C:\IMPAR\enviar_whatsapp.py", line 67, in main
    subprocess.run(["python", CAMINHO_SCRIPT_ENVIO, telefone, mensagem], check=True)
    ~~~~~~~~~~~~~~^^^^^^^^^^^^^^^^^^^^^^^^^^^^^^^^^^^^^^^^^^^^^^^^^^^^^^^^^^^^^^^^^^
  File "C:\Users\ramos\AppData\Local\Programs\Python\Python313\Lib\subprocess.py", line 577, in run
    raise CalledProcessError(retcode, process.args,
                             output=stdout, stderr=stderr)
subprocess.CalledProcessError: Command '['python', 'C:/IMPAR/enviar_whatsapp.py', '+5548999181410', 'Feliz anivers·rio, M„e! \U0001f389']' returned non-zero exit status 1.

During handling of the above exception, another exception occurred:

Traceback (most recent call last):
  File "C:\IMPAR\enviar_whatsapp.py", line 78, in <module>
    main()
    ~~~~^^
  File "C:\IMPAR\enviar_whatsapp.py", line 71, in main
    print(f"[ERRO] Erro ao enviar para {telefone}: {e}")
    ~~~~~^^^^^^^^^^^^^^^^^^^^^^^^^^^^^^^^^^^^^^^^^^^^^^^
  File "C:\Users\ramos\AppData\Local\Programs\Python\Python313\Lib\encodings\cp1252.py", line 19, in encode
    return codecs.charmap_encode(input,self.errors,encoding_table)[0]
           ~~~~~~~~~~~~~~~~~~~~~^^^^^^^^^^^^^^^^^^^^^^^^^^^^^^^^^^
UnicodeEncodeError: 'charmap' codec can't encode character '\U0001f389' in position 137: character maps to <undefined>
[13:53:20] Iniciando envio pela planilha...
[13:53] Avaliando envio para M„e (+5548999181410)...
     [HORA] Agora: 27/07/2025 13:53 | Agendado: 27/07/2025 13:48
[13:53] Enviando mensagem para M„e (+5548999181410)...
Traceback (most recent call last):
  File "C:\IMPAR\enviar_whatsapp.py", line 67, in main
    subprocess.run(["python", CAMINHO_SCRIPT_ENVIO, telefone, mensagem], check=True)
    ~~~~~~~~~~~~~~^^^^^^^^^^^^^^^^^^^^^^^^^^^^^^^^^^^^^^^^^^^^^^^^^^^^^^^^^^^^^^^^^^
  File "C:\Users\ramos\AppData\Local\Programs\Python\Python313\Lib\subprocess.py", line 577, in run
    raise CalledProcessError(retcode, process.args,
                             output=stdout, stderr=stderr)
subprocess.CalledProcessError: Command '['python', 'C:/IMPAR/enviar_whatsapp.py', '+5548999181410', 'Feliz anivers·rio, M„e! \U0001f389']' returned non-zero exit status 1.

During handling of the above exception, another exception occurred:

Traceback (most recent call last):
  File "C:\IMPAR\enviar_whatsapp.py", line 78, in <module>
    main()
    ~~~~^^
  File "C:\IMPAR\enviar_whatsapp.py", line 71, in main
    print(f"[ERRO] Erro ao enviar para {telefone}: {e}")
    ~~~~~^^^^^^^^^^^^^^^^^^^^^^^^^^^^^^^^^^^^^^^^^^^^^^^
  File "C:\Users\ramos\AppData\Local\Programs\Python\Python313\Lib\encodings\cp1252.py", line 19, in encode
    return codecs.charmap_encode(input,self.errors,encoding_table)[0]
           ~~~~~~~~~~~~~~~~~~~~~^^^^^^^^^^^^^^^^^^^^^^^^^^^^^^^^^^
UnicodeEncodeError: 'charmap' codec can't encode character '\U0001f389' in position 137: character maps to <undefined>
[13:53:15] Iniciando envio pela planilha...
[13:53] Avaliando envio para M„e (+5548999181410)...
     [HORA] Agora: 27/07/2025 13:53 | Agendado: 27/07/2025 13:48
[13:53] Enviando mensagem para M„e (+5548999181410)...
Traceback (most recent call last):
  File "C:\IMPAR\enviar_whatsapp.py", line 67, in main
    subprocess.run(["python", CAMINHO_SCRIPT_ENVIO, telefone, mensagem], check=True)
    ~~~~~~~~~~~~~~^^^^^^^^^^^^^^^^^^^^^^^^^^^^^^^^^^^^^^^^^^^^^^^^^^^^^^^^^^^^^^^^^^
  File "C:\Users\ramos\AppData\Local\Programs\Python\Python313\Lib\subprocess.py", line 577, in run
    raise CalledProcessError(retcode, process.args,
                             output=stdout, stderr=stderr)
subprocess.CalledProcessError: Command '['python', 'C:/IMPAR/enviar_whatsapp.py', '+5548999181410', 'Feliz anivers·rio, M„e! \U0001f389']' returned non-zero exit status 1.

During handling of the above exception, another exception occurred:

Traceback (most recent call last):
  File "C:\IMPAR\enviar_whatsapp.py", line 78, in <module>
    main()
    ~~~~^^
  File "C:\IMPAR\enviar_whatsapp.py", line 71, in main
    print(f"[ERRO] Erro ao enviar para {telefone}: {e}")
    ~~~~~^^^^^^^^^^^^^^^^^^^^^^^^^^^^^^^^^^^^^^^^^^^^^^^
  File "C:\Users\ramos\AppData\Local\Programs\Python\Python313\Lib\encodings\cp1252.py", line 19, in encode
    return codecs.charmap_encode(input,self.errors,encoding_table)[0]
           ~~~~~~~~~~~~~~~~~~~~~^^^^^^^^^^^^^^^^^^^^^^^^^^^^^^^^^^
UnicodeEncodeError: 'charmap' codec can't encode character '\U0001f389' in position 137: character maps to <undefined>
[13:53:14] Iniciando envio pela planilha...
[13:53] Avaliando envio para M„e (+5548999181410)...
     [HORA] Agora: 27/07/2025 13:53 | Agendado: 27/07/2025 13:48
[13:53] Enviando mensagem para M„e (+5548999181410)...
Traceback (most recent call last):
  File "C:\IMPAR\enviar_whatsapp.py", line 67, in main
    subprocess.run(["python", CAMINHO_SCRIPT_ENVIO, telefone, mensagem], check=True)
    ~~~~~~~~~~~~~~^^^^^^^^^^^^^^^^^^^^^^^^^^^^^^^^^^^^^^^^^^^^^^^^^^^^^^^^^^^^^^^^^^
  File "C:\Users\ramos\AppData\Local\Programs\Python\Python313\Lib\subprocess.py", line 577, in run
    raise CalledProcessError(retcode, process.args,
                             output=stdout, stderr=stderr)
subprocess.CalledProcessError: Command '['python', 'C:/IMPAR/enviar_whatsapp.py', '+5548999181410', 'Feliz anivers·rio, M„e! \U0001f389']' returned non-zero exit status 1.

During handling of the above exception, another exception occurred:

Traceback (most recent call last):
  File "C:\IMPAR\enviar_whatsapp.py", line 78, in <module>
    main()
    ~~~~^^
  File "C:\IMPAR\enviar_whatsapp.py", line 71, in main
    print(f"[ERRO] Erro ao enviar para {telefone}: {e}")
    ~~~~~^^^^^^^^^^^^^^^^^^^^^^^^^^^^^^^^^^^^^^^^^^^^^^^
  File "C:\Users\ramos\AppData\Local\Programs\Python\Python313\Lib\encodings\cp1252.py", line 19, in encode
    return codecs.charmap_encode(input,self.errors,encoding_table)[0]
           ~~~~~~~~~~~~~~~~~~~~~^^^^^^^^^^^^^^^^^^^^^^^^^^^^^^^^^^
UnicodeEncodeError: 'charmap' codec can't encode character '\U0001f389' in position 137: character maps to <undefined>
[13:53:11] Iniciando envio pela planilha...
[13:53] Avaliando envio para M„e (+5548999181410)...
     [HORA] Agora: 27/07/2025 13:53 | Agendado: 27/07/2025 13:48
[13:53] Enviando mensagem para M„e (+5548999181410)...
Traceback (most recent call last):
  File "C:\IMPAR\enviar_whatsapp.py", line 67, in main
    subprocess.run(["python", CAMINHO_SCRIPT_ENVIO, telefone, mensagem], check=True)
    ~~~~~~~~~~~~~~^^^^^^^^^^^^^^^^^^^^^^^^^^^^^^^^^^^^^^^^^^^^^^^^^^^^^^^^^^^^^^^^^^
  File "C:\Users\ramos\AppData\Local\Programs\Python\Python313\Lib\subprocess.py", line 577, in run
    raise CalledProcessError(retcode, process.args,
                             output=stdout, stderr=stderr)
subprocess.CalledProcessError: Command '['python', 'C:/IMPAR/enviar_whatsapp.py', '+5548999181410', 'Feliz anivers·rio, M„e! \U0001f389']' returned non-zero exit status 1.

During handling of the above exception, another exception occurred:

Traceback (most recent call last):
  File "C:\IMPAR\enviar_whatsapp.py", line 78, in <module>
    main()
    ~~~~^^
  File "C:\IMPAR\enviar_whatsapp.py", line 71, in main
    print(f"[ERRO] Erro ao enviar para {telefone}: {e}")
    ~~~~~^^^^^^^^^^^^^^^^^^^^^^^^^^^^^^^^^^^^^^^^^^^^^^^
  File "C:\Users\ramos\AppData\Local\Programs\Python\Python313\Lib\encodings\cp1252.py", line 19, in encode
    return codecs.charmap_encode(input,self.errors,encoding_table)[0]
           ~~~~~~~~~~~~~~~~~~~~~^^^^^^^^^^^^^^^^^^^^^^^^^^^^^^^^^^
UnicodeEncodeError: 'charmap' codec can't encode character '\U0001f389' in position 137: character maps to <undefined>
[13:53:08] Iniciando envio pela planilha...
[13:53] Avaliando envio para M„e (+5548999181410)...
     [HORA] Agora: 27/07/2025 13:53 | Agendado: 27/07/2025 13:48
[13:53] Enviando mensagem para M„e (+5548999181410)...
Traceback (most recent call last):
  File "C:\IMPAR\enviar_whatsapp.py", line 67, in main
    subprocess.run(["python", CAMINHO_SCRIPT_ENVIO, telefone, mensagem], check=True)
    ~~~~~~~~~~~~~~^^^^^^^^^^^^^^^^^^^^^^^^^^^^^^^^^^^^^^^^^^^^^^^^^^^^^^^^^^^^^^^^^^
  File "C:\Users\ramos\AppData\Local\Programs\Python\Python313\Lib\subprocess.py", line 577, in run
    raise CalledProcessError(retcode, process.args,
                             output=stdout, stderr=stderr)
subprocess.CalledProcessError: Command '['python', 'C:/IMPAR/enviar_whatsapp.py', '+5548999181410', 'Feliz anivers·rio, M„e! \U0001f389']' returned non-zero exit status 1.

During handling of the above exception, another exception occurred:

Traceback (most recent call last):
  File "C:\IMPAR\enviar_whatsapp.py", line 78, in <module>
    main()
    ~~~~^^
  File "C:\IMPAR\enviar_whatsapp.py", line 71, in main
    print(f"[ERRO] Erro ao enviar para {telefone}: {e}")
    ~~~~~^^^^^^^^^^^^^^^^^^^^^^^^^^^^^^^^^^^^^^^^^^^^^^^
  File "C:\Users\ramos\AppData\Local\Programs\Python\Python313\Lib\encodings\cp1252.py", line 19, in encode
    return codecs.charmap_encode(input,self.errors,encoding_table)[0]
           ~~~~~~~~~~~~~~~~~~~~~^^^^^^^^^^^^^^^^^^^^^^^^^^^^^^^^^^
UnicodeEncodeError: 'charmap' codec can't encode character '\U0001f389' in position 137: character maps to <undefined>
[13:53:07] Iniciando envio pela planilha...
[13:53] Avaliando envio para M„e (+5548999181410)...
     [HORA] Agora: 27/07/2025 13:53 | Agendado: 27/07/2025 13:48
[13:53] Enviando mensagem para M„e (+5548999181410)...
Traceback (most recent call last):
  File "C:\IMPAR\enviar_whatsapp.py", line 67, in main
    subprocess.run(["python", CAMINHO_SCRIPT_ENVIO, telefone, mensagem], check=True)
    ~~~~~~~~~~~~~~^^^^^^^^^^^^^^^^^^^^^^^^^^^^^^^^^^^^^^^^^^^^^^^^^^^^^^^^^^^^^^^^^^
  File "C:\Users\ramos\AppData\Local\Programs\Python\Python313\Lib\subprocess.py", line 577, in run
    raise CalledProcessError(retcode, process.args,
                             output=stdout, stderr=stderr)
subprocess.CalledProcessError: Command '['python', 'C:/IMPAR/enviar_whatsapp.py', '+5548999181410', 'Feliz anivers·rio, M„e! \U0001f389']' returned non-zero exit status 1.

During handling of the above exception, another exception occurred:

Traceback (most recent call last):
  File "C:\IMPAR\enviar_whatsapp.py", line 78, in <module>
    main()
    ~~~~^^
  File "C:\IMPAR\enviar_whatsapp.py", line 71, in main
    print(f"[ERRO] Erro ao enviar para {telefone}: {e}")
    ~~~~~^^^^^^^^^^^^^^^^^^^^^^^^^^^^^^^^^^^^^^^^^^^^^^^
  File "C:\Users\ramos\AppData\Local\Programs\Python\Python313\Lib\encodings\cp1252.py", line 19, in encode
    return codecs.charmap_encode(input,self.errors,encoding_table)[0]
           ~~~~~~~~~~~~~~~~~~~~~^^^^^^^^^^^^^^^^^^^^^^^^^^^^^^^^^^
UnicodeEncodeError: 'charmap' codec can't encode character '\U0001f389' in position 137: character maps to <undefined>
[13:53:02] Iniciando envio pela planilha...
[13:53] Avaliando envio para M„e (+5548999181410)...
     [HORA] Agora: 27/07/2025 13:53 | Agendado: 27/07/2025 13:48
[13:53] Enviando mensagem para M„e (+5548999181410)...
Traceback (most recent call last):
  File "C:\IMPAR\enviar_whatsapp.py", line 67, in main
    subprocess.run(["python", CAMINHO_SCRIPT_ENVIO, telefone, mensagem], check=True)
    ~~~~~~~~~~~~~~^^^^^^^^^^^^^^^^^^^^^^^^^^^^^^^^^^^^^^^^^^^^^^^^^^^^^^^^^^^^^^^^^^
  File "C:\Users\ramos\AppData\Local\Programs\Python\Python313\Lib\subprocess.py", line 577, in run
    raise CalledProcessError(retcode, process.args,
                             output=stdout, stderr=stderr)
subprocess.CalledProcessError: Command '['python', 'C:/IMPAR/enviar_whatsapp.py', '+5548999181410', 'Feliz anivers·rio, M„e! \U0001f389']' returned non-zero exit status 1.

During handling of the above exception, another exception occurred:

Traceback (most recent call last):
  File "C:\IMPAR\enviar_whatsapp.py", line 78, in <module>
    main()
    ~~~~^^
  File "C:\IMPAR\enviar_whatsapp.py", line 71, in main
    print(f"[ERRO] Erro ao enviar para {telefone}: {e}")
    ~~~~~^^^^^^^^^^^^^^^^^^^^^^^^^^^^^^^^^^^^^^^^^^^^^^^
  File "C:\Users\ramos\AppData\Local\Programs\Python\Python313\Lib\encodings\cp1252.py", line 19, in encode
    return codecs.charmap_encode(input,self.errors,encoding_table)[0]
           ~~~~~~~~~~~~~~~~~~~~~^^^^^^^^^^^^^^^^^^^^^^^^^^^^^^^^^^
UnicodeEncodeError: 'charmap' codec can't encode character '\U0001f389' in position 137: character maps to <undefined>
[13:53:01] Iniciando envio pela planilha...
[13:53] Avaliando envio para M„e (+5548999181410)...
     [HORA] Agora: 27/07/2025 13:53 | Agendado: 27/07/2025 13:48
[13:53] Enviando mensagem para M„e (+5548999181410)...
Traceback (most recent call last):
  File "C:\IMPAR\enviar_whatsapp.py", line 67, in main
    subprocess.run(["python", CAMINHO_SCRIPT_ENVIO, telefone, mensagem], check=True)
    ~~~~~~~~~~~~~~^^^^^^^^^^^^^^^^^^^^^^^^^^^^^^^^^^^^^^^^^^^^^^^^^^^^^^^^^^^^^^^^^^
  File "C:\Users\ramos\AppData\Local\Programs\Python\Python313\Lib\subprocess.py", line 577, in run
    raise CalledProcessError(retcode, process.args,
                             output=stdout, stderr=stderr)
subprocess.CalledProcessError: Command '['python', 'C:/IMPAR/enviar_whatsapp.py', '+5548999181410', 'Feliz anivers·rio, M„e! \U0001f389']' returned non-zero exit status 1.

During handling of the above exception, another exception occurred:

Traceback (most recent call last):
  File "C:\IMPAR\enviar_whatsapp.py", line 78, in <module>
    main()
    ~~~~^^
  File "C:\IMPAR\enviar_whatsapp.py", line 71, in main
    print(f"[ERRO] Erro ao enviar para {telefone}: {e}")
    ~~~~~^^^^^^^^^^^^^^^^^^^^^^^^^^^^^^^^^^^^^^^^^^^^^^^
  File "C:\Users\ramos\AppData\Local\Programs\Python\Python313\Lib\encodings\cp1252.py", line 19, in encode
    return codecs.charmap_encode(input,self.errors,encoding_table)[0]
           ~~~~~~~~~~~~~~~~~~~~~^^^^^^^^^^^^^^^^^^^^^^^^^^^^^^^^^^
UnicodeEncodeError: 'charmap' codec can't encode character '\U0001f389' in position 137: character maps to <undefined>
[13:53:00] Iniciando envio pela planilha...
[13:53] Avaliando envio para M„e (+5548999181410)...
     [HORA] Agora: 27/07/2025 13:53 | Agendado: 27/07/2025 13:48
[13:53] Enviando mensagem para M„e (+5548999181410)...
Traceback (most recent call last):
  File "C:\IMPAR\enviar_whatsapp.py", line 67, in main
    subprocess.run(["python", CAMINHO_SCRIPT_ENVIO, telefone, mensagem], check=True)
    ~~~~~~~~~~~~~~^^^^^^^^^^^^^^^^^^^^^^^^^^^^^^^^^^^^^^^^^^^^^^^^^^^^^^^^^^^^^^^^^^
  File "C:\Users\ramos\AppData\Local\Programs\Python\Python313\Lib\subprocess.py", line 577, in run
    raise CalledProcessError(retcode, process.args,
                             output=stdout, stderr=stderr)
subprocess.CalledProcessError: Command '['python', 'C:/IMPAR/enviar_whatsapp.py', '+5548999181410', 'Feliz anivers·rio, M„e! \U0001f389']' returned non-zero exit status 1.

During handling of the above exception, another exception occurred:

Traceback (most recent call last):
  File "C:\IMPAR\enviar_whatsapp.py", line 78, in <module>
    main()
    ~~~~^^
  File "C:\IMPAR\enviar_whatsapp.py", line 71, in main
    print(f"[ERRO] Erro ao enviar para {telefone}: {e}")
    ~~~~~^^^^^^^^^^^^^^^^^^^^^^^^^^^^^^^^^^^^^^^^^^^^^^^
  File "C:\Users\ramos\AppData\Local\Programs\Python\Python313\Lib\encodings\cp1252.py", line 19, in encode
    return codecs.charmap_encode(input,self.errors,encoding_table)[0]
           ~~~~~~~~~~~~~~~~~~~~~^^^^^^^^^^^^^^^^^^^^^^^^^^^^^^^^^^
UnicodeEncodeError: 'charmap' codec can't encode character '\U0001f389' in position 137: character maps to <undefined>
[13:52:54] Iniciando envio pela planilha...
[13:52] Avaliando envio para M„e (+5548999181410)...
     [HORA] Agora: 27/07/2025 13:52 | Agendado: 27/07/2025 13:48
[13:52] Enviando mensagem para M„e (+5548999181410)...
Traceback (most recent call last):
  File "C:\IMPAR\enviar_whatsapp.py", line 67, in main
    subprocess.run(["python", CAMINHO_SCRIPT_ENVIO, telefone, mensagem], check=True)
    ~~~~~~~~~~~~~~^^^^^^^^^^^^^^^^^^^^^^^^^^^^^^^^^^^^^^^^^^^^^^^^^^^^^^^^^^^^^^^^^^
  File "C:\Users\ramos\AppData\Local\Programs\Python\Python313\Lib\subprocess.py", line 577, in run
    raise CalledProcessError(retcode, process.args,
                             output=stdout, stderr=stderr)
subprocess.CalledProcessError: Command '['python', 'C:/IMPAR/enviar_whatsapp.py', '+5548999181410', 'Feliz anivers·rio, M„e! \U0001f389']' returned non-zero exit status 1.

During handling of the above exception, another exception occurred:

Traceback (most recent call last):
  File "C:\IMPAR\enviar_whatsapp.py", line 78, in <module>
    main()
    ~~~~^^
  File "C:\IMPAR\enviar_whatsapp.py", line 71, in main
    print(f"[ERRO] Erro ao enviar para {telefone}: {e}")
    ~~~~~^^^^^^^^^^^^^^^^^^^^^^^^^^^^^^^^^^^^^^^^^^^^^^^
  File "C:\Users\ramos\AppData\Local\Programs\Python\Python313\Lib\encodings\cp1252.py", line 19, in encode
    return codecs.charmap_encode(input,self.errors,encoding_table)[0]
           ~~~~~~~~~~~~~~~~~~~~~^^^^^^^^^^^^^^^^^^^^^^^^^^^^^^^^^^
UnicodeEncodeError: 'charmap' codec can't encode character '\U0001f389' in position 137: character maps to <undefined>
[13:52:53] Iniciando envio pela planilha...
[13:52] Avaliando envio para M„e (+5548999181410)...
     [HORA] Agora: 27/07/2025 13:52 | Agendado: 27/07/2025 13:48
[13:52] Enviando mensagem para M„e (+5548999181410)...
Traceback (most recent call last):
  File "C:\IMPAR\enviar_whatsapp.py", line 67, in main
    subprocess.run(["python", CAMINHO_SCRIPT_ENVIO, telefone, mensagem], check=True)
    ~~~~~~~~~~~~~~^^^^^^^^^^^^^^^^^^^^^^^^^^^^^^^^^^^^^^^^^^^^^^^^^^^^^^^^^^^^^^^^^^
  File "C:\Users\ramos\AppData\Local\Programs\Python\Python313\Lib\subprocess.py", line 577, in run
    raise CalledProcessError(retcode, process.args,
                             output=stdout, stderr=stderr)
subprocess.CalledProcessError: Command '['python', 'C:/IMPAR/enviar_whatsapp.py', '+5548999181410', 'Feliz anivers·rio, M„e! \U0001f389']' returned non-zero exit status 1.

During handling of the above exception, another exception occurred:

Traceback (most recent call last):
  File "C:\IMPAR\enviar_whatsapp.py", line 78, in <module>
    main()
    ~~~~^^
  File "C:\IMPAR\enviar_whatsapp.py", line 71, in main
    print(f"[ERRO] Erro ao enviar para {telefone}: {e}")
    ~~~~~^^^^^^^^^^^^^^^^^^^^^^^^^^^^^^^^^^^^^^^^^^^^^^^
  File "C:\Users\ramos\AppData\Local\Programs\Python\Python313\Lib\encodings\cp1252.py", line 19, in encode
    return codecs.charmap_encode(input,self.errors,encoding_table)[0]
           ~~~~~~~~~~~~~~~~~~~~~^^^^^^^^^^^^^^^^^^^^^^^^^^^^^^^^^^
UnicodeEncodeError: 'charmap' codec can't encode character '\U0001f389' in position 137: character maps to <undefined>
[13:52:50] Iniciando envio pela planilha...
[13:52] Avaliando envio para M„e (+5548999181410)...
     [HORA] Agora: 27/07/2025 13:52 | Agendado: 27/07/2025 13:48
[13:52] Enviando mensagem para M„e (+5548999181410)...
Traceback (most recent call last):
  File "C:\IMPAR\enviar_whatsapp.py", line 67, in main
    subprocess.run(["python", CAMINHO_SCRIPT_ENVIO, telefone, mensagem], check=True)
    ~~~~~~~~~~~~~~^^^^^^^^^^^^^^^^^^^^^^^^^^^^^^^^^^^^^^^^^^^^^^^^^^^^^^^^^^^^^^^^^^
  File "C:\Users\ramos\AppData\Local\Programs\Python\Python313\Lib\subprocess.py", line 577, in run
    raise CalledProcessError(retcode, process.args,
                             output=stdout, stderr=stderr)
subprocess.CalledProcessError: Command '['python', 'C:/IMPAR/enviar_whatsapp.py', '+5548999181410', 'Feliz anivers·rio, M„e! \U0001f389']' returned non-zero exit status 1.

During handling of the above exception, another exception occurred:

Traceback (most recent call last):
  File "C:\IMPAR\enviar_whatsapp.py", line 78, in <module>
    main()
    ~~~~^^
  File "C:\IMPAR\enviar_whatsapp.py", line 71, in main
    print(f"[ERRO] Erro ao enviar para {telefone}: {e}")
    ~~~~~^^^^^^^^^^^^^^^^^^^^^^^^^^^^^^^^^^^^^^^^^^^^^^^
  File "C:\Users\ramos\AppData\Local\Programs\Python\Python313\Lib\encodings\cp1252.py", line 19, in encode
    return codecs.charmap_encode(input,self.errors,encoding_table)[0]
           ~~~~~~~~~~~~~~~~~~~~~^^^^^^^^^^^^^^^^^^^^^^^^^^^^^^^^^^
UnicodeEncodeError: 'charmap' codec can't encode character '\U0001f389' in position 137: character maps to <undefined>
[13:52:47] Iniciando envio pela planilha...
[13:52] Avaliando envio para M„e (+5548999181410)...
     [HORA] Agora: 27/07/2025 13:52 | Agendado: 27/07/2025 13:48
[13:52] Enviando mensagem para M„e (+5548999181410)...
Traceback (most recent call last):
  File "C:\IMPAR\enviar_whatsapp.py", line 67, in main
    subprocess.run(["python", CAMINHO_SCRIPT_ENVIO, telefone, mensagem], check=True)
    ~~~~~~~~~~~~~~^^^^^^^^^^^^^^^^^^^^^^^^^^^^^^^^^^^^^^^^^^^^^^^^^^^^^^^^^^^^^^^^^^
  File "C:\Users\ramos\AppData\Local\Programs\Python\Python313\Lib\subprocess.py", line 577, in run
    raise CalledProcessError(retcode, process.args,
                             output=stdout, stderr=stderr)
subprocess.CalledProcessError: Command '['python', 'C:/IMPAR/enviar_whatsapp.py', '+5548999181410', 'Feliz anivers·rio, M„e! \U0001f389']' returned non-zero exit status 1.

During handling of the above exception, another exception occurred:

Traceback (most recent call last):
  File "C:\IMPAR\enviar_whatsapp.py", line 78, in <module>
    main()
    ~~~~^^
  File "C:\IMPAR\enviar_whatsapp.py", line 71, in main
    print(f"[ERRO] Erro ao enviar para {telefone}: {e}")
    ~~~~~^^^^^^^^^^^^^^^^^^^^^^^^^^^^^^^^^^^^^^^^^^^^^^^
  File "C:\Users\ramos\AppData\Local\Programs\Python\Python313\Lib\encodings\cp1252.py", line 19, in encode
    return codecs.charmap_encode(input,self.errors,encoding_table)[0]
           ~~~~~~~~~~~~~~~~~~~~~^^^^^^^^^^^^^^^^^^^^^^^^^^^^^^^^^^
UnicodeEncodeError: 'charmap' codec can't encode character '\U0001f389' in position 137: character maps to <undefined>
[13:52:41] Iniciando envio pela planilha...
[13:52] Avaliando envio para M„e (+5548999181410)...
     [HORA] Agora: 27/07/2025 13:52 | Agendado: 27/07/2025 13:48
[13:52] Enviando mensagem para M„e (+5548999181410)...
Traceback (most recent call last):
  File "C:\IMPAR\enviar_whatsapp.py", line 67, in main
    subprocess.run(["python", CAMINHO_SCRIPT_ENVIO, telefone, mensagem], check=True)
    ~~~~~~~~~~~~~~^^^^^^^^^^^^^^^^^^^^^^^^^^^^^^^^^^^^^^^^^^^^^^^^^^^^^^^^^^^^^^^^^^
  File "C:\Users\ramos\AppData\Local\Programs\Python\Python313\Lib\subprocess.py", line 577, in run
    raise CalledProcessError(retcode, process.args,
                             output=stdout, stderr=stderr)
subprocess.CalledProcessError: Command '['python', 'C:/IMPAR/enviar_whatsapp.py', '+5548999181410', 'Feliz anivers·rio, M„e! \U0001f389']' returned non-zero exit status 1.

During handling of the above exception, another exception occurred:

Traceback (most recent call last):
  File "C:\IMPAR\enviar_whatsapp.py", line 78, in <module>
    main()
    ~~~~^^
  File "C:\IMPAR\enviar_whatsapp.py", line 71, in main
    print(f"[ERRO] Erro ao enviar para {telefone}: {e}")
    ~~~~~^^^^^^^^^^^^^^^^^^^^^^^^^^^^^^^^^^^^^^^^^^^^^^^
  File "C:\Users\ramos\AppData\Local\Programs\Python\Python313\Lib\encodings\cp1252.py", line 19, in encode
    return codecs.charmap_encode(input,self.errors,encoding_table)[0]
           ~~~~~~~~~~~~~~~~~~~~~^^^^^^^^^^^^^^^^^^^^^^^^^^^^^^^^^^
UnicodeEncodeError: 'charmap' codec can't encode character '\U0001f389' in position 137: character maps to <undefined>
[13:52:25] Iniciando envio pela planilha...
[13:52] Avaliando envio para M„e (+5548999181410)...
     [HORA] Agora: 27/07/2025 13:52 | Agendado: 27/07/2025 13:48
[13:52] Enviando mensagem para M„e (+5548999181410)...
Traceback (most recent call last):
  File "C:\IMPAR\enviar_whatsapp.py", line 67, in main
    subprocess.run(["python", CAMINHO_SCRIPT_ENVIO, telefone, mensagem], check=True)
    ~~~~~~~~~~~~~~^^^^^^^^^^^^^^^^^^^^^^^^^^^^^^^^^^^^^^^^^^^^^^^^^^^^^^^^^^^^^^^^^^
  File "C:\Users\ramos\AppData\Local\Programs\Python\Python313\Lib\subprocess.py", line 577, in run
    raise CalledProcessError(retcode, process.args,
                             output=stdout, stderr=stderr)
subprocess.CalledProcessError: Command '['python', 'C:/IMPAR/enviar_whatsapp.py', '+5548999181410', 'Feliz anivers·rio, M„e! \U0001f389']' returned non-zero exit status 1.

During handling of the above exception, another exception occurred:

Traceback (most recent call last):
  File "C:\IMPAR\enviar_whatsapp.py", line 78, in <module>
    main()
    ~~~~^^
  File "C:\IMPAR\enviar_whatsapp.py", line 71, in main
    print(f"[ERRO] Erro ao enviar para {telefone}: {e}")
    ~~~~~^^^^^^^^^^^^^^^^^^^^^^^^^^^^^^^^^^^^^^^^^^^^^^^
  File "C:\Users\ramos\AppData\Local\Programs\Python\Python313\Lib\encodings\cp1252.py", line 19, in encode
    return codecs.charmap_encode(input,self.errors,encoding_table)[0]
           ~~~~~~~~~~~~~~~~~~~~~^^^^^^^^^^^^^^^^^^^^^^^^^^^^^^^^^^
UnicodeEncodeError: 'charmap' codec can't encode character '\U0001f389' in position 137: character maps to <undefined>
[13:52:23] Iniciando envio pela planilha...
[13:52] Avaliando envio para M„e (+5548999181410)...
     [HORA] Agora: 27/07/2025 13:52 | Agendado: 27/07/2025 13:48
[13:52] Enviando mensagem para M„e (+5548999181410)...
Traceback (most recent call last):
  File "C:\IMPAR\enviar_whatsapp.py", line 67, in main
    subprocess.run(["python", CAMINHO_SCRIPT_ENVIO, telefone, mensagem], check=True)
    ~~~~~~~~~~~~~~^^^^^^^^^^^^^^^^^^^^^^^^^^^^^^^^^^^^^^^^^^^^^^^^^^^^^^^^^^^^^^^^^^
  File "C:\Users\ramos\AppData\Local\Programs\Python\Python313\Lib\subprocess.py", line 577, in run
    raise CalledProcessError(retcode, process.args,
                             output=stdout, stderr=stderr)
subprocess.CalledProcessError: Command '['python', 'C:/IMPAR/enviar_whatsapp.py', '+5548999181410', 'Feliz anivers·rio, M„e! \U0001f389']' returned non-zero exit status 1.

During handling of the above exception, another exception occurred:

Traceback (most recent call last):
  File "C:\IMPAR\enviar_whatsapp.py", line 78, in <module>
    main()
    ~~~~^^
  File "C:\IMPAR\enviar_whatsapp.py", line 71, in main
    print(f"[ERRO] Erro ao enviar para {telefone}: {e}")
    ~~~~~^^^^^^^^^^^^^^^^^^^^^^^^^^^^^^^^^^^^^^^^^^^^^^^
  File "C:\Users\ramos\AppData\Local\Programs\Python\Python313\Lib\encodings\cp1252.py", line 19, in encode
    return codecs.charmap_encode(input,self.errors,encoding_table)[0]
           ~~~~~~~~~~~~~~~~~~~~~^^^^^^^^^^^^^^^^^^^^^^^^^^^^^^^^^^
UnicodeEncodeError: 'charmap' codec can't encode character '\U0001f389' in position 137: character maps to <undefined>
[13:52:18] Iniciando envio pela planilha...
[13:52] Avaliando envio para M„e (+5548999181410)...
     [HORA] Agora: 27/07/2025 13:52 | Agendado: 27/07/2025 13:48
[13:52] Enviando mensagem para M„e (+5548999181410)...
Traceback (most recent call last):
  File "C:\IMPAR\enviar_whatsapp.py", line 67, in main
    subprocess.run(["python", CAMINHO_SCRIPT_ENVIO, telefone, mensagem], check=True)
    ~~~~~~~~~~~~~~^^^^^^^^^^^^^^^^^^^^^^^^^^^^^^^^^^^^^^^^^^^^^^^^^^^^^^^^^^^^^^^^^^
  File "C:\Users\ramos\AppData\Local\Programs\Python\Python313\Lib\subprocess.py", line 577, in run
    raise CalledProcessError(retcode, process.args,
                             output=stdout, stderr=stderr)
subprocess.CalledProcessError: Command '['python', 'C:/IMPAR/enviar_whatsapp.py', '+5548999181410', 'Feliz anivers·rio, M„e! \U0001f389']' returned non-zero exit status 1.

During handling of the above exception, another exception occurred:

Traceback (most recent call last):
  File "C:\IMPAR\enviar_whatsapp.py", line 78, in <module>
    main()
    ~~~~^^
  File "C:\IMPAR\enviar_whatsapp.py", line 71, in main
    print(f"[ERRO] Erro ao enviar para {telefone}: {e}")
    ~~~~~^^^^^^^^^^^^^^^^^^^^^^^^^^^^^^^^^^^^^^^^^^^^^^^
  File "C:\Users\ramos\AppData\Local\Programs\Python\Python313\Lib\encodings\cp1252.py", line 19, in encode
    return codecs.charmap_encode(input,self.errors,encoding_table)[0]
           ~~~~~~~~~~~~~~~~~~~~~^^^^^^^^^^^^^^^^^^^^^^^^^^^^^^^^^^
UnicodeEncodeError: 'charmap' codec can't encode character '\U0001f389' in position 137: character maps to <undefined>
[13:52:17] Iniciando envio pela planilha...
[13:52] Avaliando envio para M„e (+5548999181410)...
     [HORA] Agora: 27/07/2025 13:52 | Agendado: 27/07/2025 13:48
[13:52] Enviando mensagem para M„e (+5548999181410)...
Traceback (most recent call last):
  File "C:\IMPAR\enviar_whatsapp.py", line 67, in main
    subprocess.run(["python", CAMINHO_SCRIPT_ENVIO, telefone, mensagem], check=True)
    ~~~~~~~~~~~~~~^^^^^^^^^^^^^^^^^^^^^^^^^^^^^^^^^^^^^^^^^^^^^^^^^^^^^^^^^^^^^^^^^^
  File "C:\Users\ramos\AppData\Local\Programs\Python\Python313\Lib\subprocess.py", line 577, in run
    raise CalledProcessError(retcode, process.args,
                             output=stdout, stderr=stderr)
subprocess.CalledProcessError: Command '['python', 'C:/IMPAR/enviar_whatsapp.py', '+5548999181410', 'Feliz anivers·rio, M„e! \U0001f389']' returned non-zero exit status 1.

During handling of the above exception, another exception occurred:

Traceback (most recent call last):
  File "C:\IMPAR\enviar_whatsapp.py", line 78, in <module>
    main()
    ~~~~^^
  File "C:\IMPAR\enviar_whatsapp.py", line 71, in main
    print(f"[ERRO] Erro ao enviar para {telefone}: {e}")
    ~~~~~^^^^^^^^^^^^^^^^^^^^^^^^^^^^^^^^^^^^^^^^^^^^^^^
  File "C:\Users\ramos\AppData\Local\Programs\Python\Python313\Lib\encodings\cp1252.py", line 19, in encode
    return codecs.charmap_encode(input,self.errors,encoding_table)[0]
           ~~~~~~~~~~~~~~~~~~~~~^^^^^^^^^^^^^^^^^^^^^^^^^^^^^^^^^^
UnicodeEncodeError: 'charmap' codec can't encode character '\U0001f389' in position 137: character maps to <undefined>
[13:52:16] Iniciando envio pela planilha...
[13:52] Avaliando envio para M„e (+5548999181410)...
     [HORA] Agora: 27/07/2025 13:52 | Agendado: 27/07/2025 13:48
[13:52] Enviando mensagem para M„e (+5548999181410)...
Traceback (most recent call last):
  File "C:\IMPAR\enviar_whatsapp.py", line 67, in main
    subprocess.run(["python", CAMINHO_SCRIPT_ENVIO, telefone, mensagem], check=True)
    ~~~~~~~~~~~~~~^^^^^^^^^^^^^^^^^^^^^^^^^^^^^^^^^^^^^^^^^^^^^^^^^^^^^^^^^^^^^^^^^^
  File "C:\Users\ramos\AppData\Local\Programs\Python\Python313\Lib\subprocess.py", line 577, in run
    raise CalledProcessError(retcode, process.args,
                             output=stdout, stderr=stderr)
subprocess.CalledProcessError: Command '['python', 'C:/IMPAR/enviar_whatsapp.py', '+5548999181410', 'Feliz anivers·rio, M„e! \U0001f389']' returned non-zero exit status 1.

During handling of the above exception, another exception occurred:

Traceback (most recent call last):
  File "C:\IMPAR\enviar_whatsapp.py", line 78, in <module>
    main()
    ~~~~^^
  File "C:\IMPAR\enviar_whatsapp.py", line 71, in main
    print(f"[ERRO] Erro ao enviar para {telefone}: {e}")
    ~~~~~^^^^^^^^^^^^^^^^^^^^^^^^^^^^^^^^^^^^^^^^^^^^^^^
  File "C:\Users\ramos\AppData\Local\Programs\Python\Python313\Lib\encodings\cp1252.py", line 19, in encode
    return codecs.charmap_encode(input,self.errors,encoding_table)[0]
           ~~~~~~~~~~~~~~~~~~~~~^^^^^^^^^^^^^^^^^^^^^^^^^^^^^^^^^^
UnicodeEncodeError: 'charmap' codec can't encode character '\U0001f389' in position 137: character maps to <undefined>
[13:52:11] Iniciando envio pela planilha...
[13:52] Avaliando envio para M„e (+5548999181410)...
     [HORA] Agora: 27/07/2025 13:52 | Agendado: 27/07/2025 13:48
[13:52] Enviando mensagem para M„e (+5548999181410)...
Traceback (most recent call last):
  File "C:\IMPAR\enviar_whatsapp.py", line 67, in main
    subprocess.run(["python", CAMINHO_SCRIPT_ENVIO, telefone, mensagem], check=True)
    ~~~~~~~~~~~~~~^^^^^^^^^^^^^^^^^^^^^^^^^^^^^^^^^^^^^^^^^^^^^^^^^^^^^^^^^^^^^^^^^^
  File "C:\Users\ramos\AppData\Local\Programs\Python\Python313\Lib\subprocess.py", line 577, in run
    raise CalledProcessError(retcode, process.args,
                             output=stdout, stderr=stderr)
subprocess.CalledProcessError: Command '['python', 'C:/IMPAR/enviar_whatsapp.py', '+5548999181410', 'Feliz anivers·rio, M„e! \U0001f389']' returned non-zero exit status 1.

During handling of the above exception, another exception occurred:

Traceback (most recent call last):
  File "C:\IMPAR\enviar_whatsapp.py", line 78, in <module>
    main()
    ~~~~^^
  File "C:\IMPAR\enviar_whatsapp.py", line 71, in main
    print(f"[ERRO] Erro ao enviar para {telefone}: {e}")
    ~~~~~^^^^^^^^^^^^^^^^^^^^^^^^^^^^^^^^^^^^^^^^^^^^^^^
  File "C:\Users\ramos\AppData\Local\Programs\Python\Python313\Lib\encodings\cp1252.py", line 19, in encode
    return codecs.charmap_encode(input,self.errors,encoding_table)[0]
           ~~~~~~~~~~~~~~~~~~~~~^^^^^^^^^^^^^^^^^^^^^^^^^^^^^^^^^^
UnicodeEncodeError: 'charmap' codec can't encode character '\U0001f389' in position 137: character maps to <undefined>
[13:52:09] Iniciando envio pela planilha...
[13:52] Avaliando envio para M„e (+5548999181410)...
     [HORA] Agora: 27/07/2025 13:52 | Agendado: 27/07/2025 13:48
[13:52] Enviando mensagem para M„e (+5548999181410)...
Traceback (most recent call last):
  File "C:\IMPAR\enviar_whatsapp.py", line 67, in main
    subprocess.run(["python", CAMINHO_SCRIPT_ENVIO, telefone, mensagem], check=True)
    ~~~~~~~~~~~~~~^^^^^^^^^^^^^^^^^^^^^^^^^^^^^^^^^^^^^^^^^^^^^^^^^^^^^^^^^^^^^^^^^^
  File "C:\Users\ramos\AppData\Local\Programs\Python\Python313\Lib\subprocess.py", line 577, in run
    raise CalledProcessError(retcode, process.args,
                             output=stdout, stderr=stderr)
subprocess.CalledProcessError: Command '['python', 'C:/IMPAR/enviar_whatsapp.py', '+5548999181410', 'Feliz anivers·rio, M„e! \U0001f389']' returned non-zero exit status 1.

During handling of the above exception, another exception occurred:

Traceback (most recent call last):
  File "C:\IMPAR\enviar_whatsapp.py", line 78, in <module>
    main()
    ~~~~^^
  File "C:\IMPAR\enviar_whatsapp.py", line 71, in main
    print(f"[ERRO] Erro ao enviar para {telefone}: {e}")
    ~~~~~^^^^^^^^^^^^^^^^^^^^^^^^^^^^^^^^^^^^^^^^^^^^^^^
  File "C:\Users\ramos\AppData\Local\Programs\Python\Python313\Lib\encodings\cp1252.py", line 19, in encode
    return codecs.charmap_encode(input,self.errors,encoding_table)[0]
           ~~~~~~~~~~~~~~~~~~~~~^^^^^^^^^^^^^^^^^^^^^^^^^^^^^^^^^^
UnicodeEncodeError: 'charmap' codec can't encode character '\U0001f389' in position 137: character maps to <undefined>
[13:52:05] Iniciando envio pela planilha...
[13:52] Avaliando envio para M„e (+5548999181410)...
     [HORA] Agora: 27/07/2025 13:52 | Agendado: 27/07/2025 13:48
[13:52] Enviando mensagem para M„e (+5548999181410)...
Traceback (most recent call last):
  File "C:\IMPAR\enviar_whatsapp.py", line 67, in main
    subprocess.run(["python", CAMINHO_SCRIPT_ENVIO, telefone, mensagem], check=True)
    ~~~~~~~~~~~~~~^^^^^^^^^^^^^^^^^^^^^^^^^^^^^^^^^^^^^^^^^^^^^^^^^^^^^^^^^^^^^^^^^^
  File "C:\Users\ramos\AppData\Local\Programs\Python\Python313\Lib\subprocess.py", line 577, in run
    raise CalledProcessError(retcode, process.args,
                             output=stdout, stderr=stderr)
subprocess.CalledProcessError: Command '['python', 'C:/IMPAR/enviar_whatsapp.py', '+5548999181410', 'Feliz anivers·rio, M„e! \U0001f389']' returned non-zero exit status 1.

During handling of the above exception, another exception occurred:

Traceback (most recent call last):
  File "C:\IMPAR\enviar_whatsapp.py", line 78, in <module>
    main()
    ~~~~^^
  File "C:\IMPAR\enviar_whatsapp.py", line 71, in main
    print(f"[ERRO] Erro ao enviar para {telefone}: {e}")
    ~~~~~^^^^^^^^^^^^^^^^^^^^^^^^^^^^^^^^^^^^^^^^^^^^^^^
  File "C:\Users\ramos\AppData\Local\Programs\Python\Python313\Lib\encodings\cp1252.py", line 19, in encode
    return codecs.charmap_encode(input,self.errors,encoding_table)[0]
           ~~~~~~~~~~~~~~~~~~~~~^^^^^^^^^^^^^^^^^^^^^^^^^^^^^^^^^^
UnicodeEncodeError: 'charmap' codec can't encode character '\U0001f389' in position 137: character maps to <undefined>
[13:52:03] Iniciando envio pela planilha...
[13:52] Avaliando envio para M„e (+5548999181410)...
     [HORA] Agora: 27/07/2025 13:52 | Agendado: 27/07/2025 13:48
[13:52] Enviando mensagem para M„e (+5548999181410)...
Traceback (most recent call last):
  File "C:\IMPAR\enviar_whatsapp.py", line 67, in main
    subprocess.run(["python", CAMINHO_SCRIPT_ENVIO, telefone, mensagem], check=True)
    ~~~~~~~~~~~~~~^^^^^^^^^^^^^^^^^^^^^^^^^^^^^^^^^^^^^^^^^^^^^^^^^^^^^^^^^^^^^^^^^^
  File "C:\Users\ramos\AppData\Local\Programs\Python\Python313\Lib\subprocess.py", line 577, in run
    raise CalledProcessError(retcode, process.args,
                             output=stdout, stderr=stderr)
subprocess.CalledProcessError: Command '['python', 'C:/IMPAR/enviar_whatsapp.py', '+5548999181410', 'Feliz anivers·rio, M„e! \U0001f389']' returned non-zero exit status 1.

During handling of the above exception, another exception occurred:

Traceback (most recent call last):
  File "C:\IMPAR\enviar_whatsapp.py", line 78, in <module>
    main()
    ~~~~^^
  File "C:\IMPAR\enviar_whatsapp.py", line 71, in main
    print(f"[ERRO] Erro ao enviar para {telefone}: {e}")
    ~~~~~^^^^^^^^^^^^^^^^^^^^^^^^^^^^^^^^^^^^^^^^^^^^^^^
  File "C:\Users\ramos\AppData\Local\Programs\Python\Python313\Lib\encodings\cp1252.py", line 19, in encode
    return codecs.charmap_encode(input,self.errors,encoding_table)[0]
           ~~~~~~~~~~~~~~~~~~~~~^^^^^^^^^^^^^^^^^^^^^^^^^^^^^^^^^^
UnicodeEncodeError: 'charmap' codec can't encode character '\U0001f389' in position 137: character maps to <undefined>
[13:52:02] Iniciando envio pela planilha...
[13:52] Avaliando envio para M„e (+5548999181410)...
     [HORA] Agora: 27/07/2025 13:52 | Agendado: 27/07/2025 13:48
[13:52] Enviando mensagem para M„e (+5548999181410)...
Traceback (most recent call last):
  File "C:\IMPAR\enviar_whatsapp.py", line 67, in main
    subprocess.run(["python", CAMINHO_SCRIPT_ENVIO, telefone, mensagem], check=True)
    ~~~~~~~~~~~~~~^^^^^^^^^^^^^^^^^^^^^^^^^^^^^^^^^^^^^^^^^^^^^^^^^^^^^^^^^^^^^^^^^^
  File "C:\Users\ramos\AppData\Local\Programs\Python\Python313\Lib\subprocess.py", line 577, in run
    raise CalledProcessError(retcode, process.args,
                             output=stdout, stderr=stderr)
subprocess.CalledProcessError: Command '['python', 'C:/IMPAR/enviar_whatsapp.py', '+5548999181410', 'Feliz anivers·rio, M„e! \U0001f389']' returned non-zero exit status 1.

During handling of the above exception, another exception occurred:

Traceback (most recent call last):
  File "C:\IMPAR\enviar_whatsapp.py", line 78, in <module>
    main()
    ~~~~^^
  File "C:\IMPAR\enviar_whatsapp.py", line 71, in main
    print(f"[ERRO] Erro ao enviar para {telefone}: {e}")
    ~~~~~^^^^^^^^^^^^^^^^^^^^^^^^^^^^^^^^^^^^^^^^^^^^^^^
  File "C:\Users\ramos\AppData\Local\Programs\Python\Python313\Lib\encodings\cp1252.py", line 19, in encode
    return codecs.charmap_encode(input,self.errors,encoding_table)[0]
           ~~~~~~~~~~~~~~~~~~~~~^^^^^^^^^^^^^^^^^^^^^^^^^^^^^^^^^^
UnicodeEncodeError: 'charmap' codec can't encode character '\U0001f389' in position 137: character maps to <undefined>
[13:52:00] Iniciando envio pela planilha...
[13:52] Avaliando envio para M„e (+5548999181410)...
     [HORA] Agora: 27/07/2025 13:52 | Agendado: 27/07/2025 13:48
[13:52] Enviando mensagem para M„e (+5548999181410)...
Traceback (most recent call last):
  File "C:\IMPAR\enviar_whatsapp.py", line 67, in main
    subprocess.run(["python", CAMINHO_SCRIPT_ENVIO, telefone, mensagem], check=True)
    ~~~~~~~~~~~~~~^^^^^^^^^^^^^^^^^^^^^^^^^^^^^^^^^^^^^^^^^^^^^^^^^^^^^^^^^^^^^^^^^^
  File "C:\Users\ramos\AppData\Local\Programs\Python\Python313\Lib\subprocess.py", line 577, in run
    raise CalledProcessError(retcode, process.args,
                             output=stdout, stderr=stderr)
subprocess.CalledProcessError: Command '['python', 'C:/IMPAR/enviar_whatsapp.py', '+5548999181410', 'Feliz anivers·rio, M„e! \U0001f389']' returned non-zero exit status 1.

During handling of the above exception, another exception occurred:

Traceback (most recent call last):
  File "C:\IMPAR\enviar_whatsapp.py", line 78, in <module>
    main()
    ~~~~^^
  File "C:\IMPAR\enviar_whatsapp.py", line 71, in main
    print(f"[ERRO] Erro ao enviar para {telefone}: {e}")
    ~~~~~^^^^^^^^^^^^^^^^^^^^^^^^^^^^^^^^^^^^^^^^^^^^^^^
  File "C:\Users\ramos\AppData\Local\Programs\Python\Python313\Lib\encodings\cp1252.py", line 19, in encode
    return codecs.charmap_encode(input,self.errors,encoding_table)[0]
           ~~~~~~~~~~~~~~~~~~~~~^^^^^^^^^^^^^^^^^^^^^^^^^^^^^^^^^^
UnicodeEncodeError: 'charmap' codec can't encode character '\U0001f389' in position 137: character maps to <undefined>
[13:51:59] Iniciando envio pela planilha...
[13:51] Avaliando envio para M„e (+5548999181410)...
     [HORA] Agora: 27/07/2025 13:51 | Agendado: 27/07/2025 13:48
[13:51] Enviando mensagem para M„e (+5548999181410)...
Traceback (most recent call last):
  File "C:\IMPAR\enviar_whatsapp.py", line 67, in main
    subprocess.run(["python", CAMINHO_SCRIPT_ENVIO, telefone, mensagem], check=True)
    ~~~~~~~~~~~~~~^^^^^^^^^^^^^^^^^^^^^^^^^^^^^^^^^^^^^^^^^^^^^^^^^^^^^^^^^^^^^^^^^^
  File "C:\Users\ramos\AppData\Local\Programs\Python\Python313\Lib\subprocess.py", line 577, in run
    raise CalledProcessError(retcode, process.args,
                             output=stdout, stderr=stderr)
subprocess.CalledProcessError: Command '['python', 'C:/IMPAR/enviar_whatsapp.py', '+5548999181410', 'Feliz anivers·rio, M„e! \U0001f389']' returned non-zero exit status 1.

During handling of the above exception, another exception occurred:

Traceback (most recent call last):
  File "C:\IMPAR\enviar_whatsapp.py", line 78, in <module>
    main()
    ~~~~^^
  File "C:\IMPAR\enviar_whatsapp.py", line 71, in main
    print(f"[ERRO] Erro ao enviar para {telefone}: {e}")
    ~~~~~^^^^^^^^^^^^^^^^^^^^^^^^^^^^^^^^^^^^^^^^^^^^^^^
  File "C:\Users\ramos\AppData\Local\Programs\Python\Python313\Lib\encodings\cp1252.py", line 19, in encode
    return codecs.charmap_encode(input,self.errors,encoding_table)[0]
           ~~~~~~~~~~~~~~~~~~~~~^^^^^^^^^^^^^^^^^^^^^^^^^^^^^^^^^^
UnicodeEncodeError: 'charmap' codec can't encode character '\U0001f389' in position 137: character maps to <undefined>
[13:51:57] Iniciando envio pela planilha...
[13:51] Avaliando envio para M„e (+5548999181410)...
     [HORA] Agora: 27/07/2025 13:51 | Agendado: 27/07/2025 13:48
[13:51] Enviando mensagem para M„e (+5548999181410)...
Traceback (most recent call last):
  File "C:\IMPAR\enviar_whatsapp.py", line 67, in main
    subprocess.run(["python", CAMINHO_SCRIPT_ENVIO, telefone, mensagem], check=True)
    ~~~~~~~~~~~~~~^^^^^^^^^^^^^^^^^^^^^^^^^^^^^^^^^^^^^^^^^^^^^^^^^^^^^^^^^^^^^^^^^^
  File "C:\Users\ramos\AppData\Local\Programs\Python\Python313\Lib\subprocess.py", line 577, in run
    raise CalledProcessError(retcode, process.args,
                             output=stdout, stderr=stderr)
subprocess.CalledProcessError: Command '['python', 'C:/IMPAR/enviar_whatsapp.py', '+5548999181410', 'Feliz anivers·rio, M„e! \U0001f389']' returned non-zero exit status 1.

During handling of the above exception, another exception occurred:

Traceback (most recent call last):
  File "C:\IMPAR\enviar_whatsapp.py", line 78, in <module>
    main()
    ~~~~^^
  File "C:\IMPAR\enviar_whatsapp.py", line 71, in main
    print(f"[ERRO] Erro ao enviar para {telefone}: {e}")
    ~~~~~^^^^^^^^^^^^^^^^^^^^^^^^^^^^^^^^^^^^^^^^^^^^^^^
  File "C:\Users\ramos\AppData\Local\Programs\Python\Python313\Lib\encodings\cp1252.py", line 19, in encode
    return codecs.charmap_encode(input,self.errors,encoding_table)[0]
           ~~~~~~~~~~~~~~~~~~~~~^^^^^^^^^^^^^^^^^^^^^^^^^^^^^^^^^^
UnicodeEncodeError: 'charmap' codec can't encode character '\U0001f389' in position 137: character maps to <undefined>
[13:51:56] Iniciando envio pela planilha...
[13:51] Avaliando envio para M„e (+5548999181410)...
     [HORA] Agora: 27/07/2025 13:51 | Agendado: 27/07/2025 13:48
[13:51] Enviando mensagem para M„e (+5548999181410)...
Traceback (most recent call last):
  File "C:\IMPAR\enviar_whatsapp.py", line 67, in main
    subprocess.run(["python", CAMINHO_SCRIPT_ENVIO, telefone, mensagem], check=True)
    ~~~~~~~~~~~~~~^^^^^^^^^^^^^^^^^^^^^^^^^^^^^^^^^^^^^^^^^^^^^^^^^^^^^^^^^^^^^^^^^^
  File "C:\Users\ramos\AppData\Local\Programs\Python\Python313\Lib\subprocess.py", line 577, in run
    raise CalledProcessError(retcode, process.args,
                             output=stdout, stderr=stderr)
subprocess.CalledProcessError: Command '['python', 'C:/IMPAR/enviar_whatsapp.py', '+5548999181410', 'Feliz anivers·rio, M„e! \U0001f389']' returned non-zero exit status 1.

During handling of the above exception, another exception occurred:

Traceback (most recent call last):
  File "C:\IMPAR\enviar_whatsapp.py", line 78, in <module>
    main()
    ~~~~^^
  File "C:\IMPAR\enviar_whatsapp.py", line 71, in main
    print(f"[ERRO] Erro ao enviar para {telefone}: {e}")
    ~~~~~^^^^^^^^^^^^^^^^^^^^^^^^^^^^^^^^^^^^^^^^^^^^^^^
  File "C:\Users\ramos\AppData\Local\Programs\Python\Python313\Lib\encodings\cp1252.py", line 19, in encode
    return codecs.charmap_encode(input,self.errors,encoding_table)[0]
           ~~~~~~~~~~~~~~~~~~~~~^^^^^^^^^^^^^^^^^^^^^^^^^^^^^^^^^^
UnicodeEncodeError: 'charmap' codec can't encode character '\U0001f389' in position 137: character maps to <undefined>
[13:51:54] Iniciando envio pela planilha...
[13:51] Avaliando envio para M„e (+5548999181410)...
     [HORA] Agora: 27/07/2025 13:51 | Agendado: 27/07/2025 13:48
[13:51] Enviando mensagem para M„e (+5548999181410)...
Traceback (most recent call last):
  File "C:\IMPAR\enviar_whatsapp.py", line 67, in main
    subprocess.run(["python", CAMINHO_SCRIPT_ENVIO, telefone, mensagem], check=True)
    ~~~~~~~~~~~~~~^^^^^^^^^^^^^^^^^^^^^^^^^^^^^^^^^^^^^^^^^^^^^^^^^^^^^^^^^^^^^^^^^^
  File "C:\Users\ramos\AppData\Local\Programs\Python\Python313\Lib\subprocess.py", line 577, in run
    raise CalledProcessError(retcode, process.args,
                             output=stdout, stderr=stderr)
subprocess.CalledProcessError: Command '['python', 'C:/IMPAR/enviar_whatsapp.py', '+5548999181410', 'Feliz anivers·rio, M„e! \U0001f389']' returned non-zero exit status 1.

During handling of the above exception, another exception occurred:

Traceback (most recent call last):
  File "C:\IMPAR\enviar_whatsapp.py", line 78, in <module>
    main()
    ~~~~^^
  File "C:\IMPAR\enviar_whatsapp.py", line 71, in main
    print(f"[ERRO] Erro ao enviar para {telefone}: {e}")
    ~~~~~^^^^^^^^^^^^^^^^^^^^^^^^^^^^^^^^^^^^^^^^^^^^^^^
  File "C:\Users\ramos\AppData\Local\Programs\Python\Python313\Lib\encodings\cp1252.py", line 19, in encode
    return codecs.charmap_encode(input,self.errors,encoding_table)[0]
           ~~~~~~~~~~~~~~~~~~~~~^^^^^^^^^^^^^^^^^^^^^^^^^^^^^^^^^^
UnicodeEncodeError: 'charmap' codec can't encode character '\U0001f389' in position 137: character maps to <undefined>
[13:51:52] Iniciando envio pela planilha...
[13:51] Avaliando envio para M„e (+5548999181410)...
     [HORA] Agora: 27/07/2025 13:51 | Agendado: 27/07/2025 13:48
[13:51] Enviando mensagem para M„e (+5548999181410)...
Traceback (most recent call last):
  File "C:\IMPAR\enviar_whatsapp.py", line 67, in main
    subprocess.run(["python", CAMINHO_SCRIPT_ENVIO, telefone, mensagem], check=True)
    ~~~~~~~~~~~~~~^^^^^^^^^^^^^^^^^^^^^^^^^^^^^^^^^^^^^^^^^^^^^^^^^^^^^^^^^^^^^^^^^^
  File "C:\Users\ramos\AppData\Local\Programs\Python\Python313\Lib\subprocess.py", line 577, in run
    raise CalledProcessError(retcode, process.args,
                             output=stdout, stderr=stderr)
subprocess.CalledProcessError: Command '['python', 'C:/IMPAR/enviar_whatsapp.py', '+5548999181410', 'Feliz anivers·rio, M„e! \U0001f389']' returned non-zero exit status 1.

During handling of the above exception, another exception occurred:

Traceback (most recent call last):
  File "C:\IMPAR\enviar_whatsapp.py", line 78, in <module>
    main()
    ~~~~^^
  File "C:\IMPAR\enviar_whatsapp.py", line 71, in main
    print(f"[ERRO] Erro ao enviar para {telefone}: {e}")
    ~~~~~^^^^^^^^^^^^^^^^^^^^^^^^^^^^^^^^^^^^^^^^^^^^^^^
  File "C:\Users\ramos\AppData\Local\Programs\Python\Python313\Lib\encodings\cp1252.py", line 19, in encode
    return codecs.charmap_encode(input,self.errors,encoding_table)[0]
           ~~~~~~~~~~~~~~~~~~~~~^^^^^^^^^^^^^^^^^^^^^^^^^^^^^^^^^^
UnicodeEncodeError: 'charmap' codec can't encode character '\U0001f389' in position 137: character maps to <undefined>
[13:51:51] Iniciando envio pela planilha...
[13:51] Avaliando envio para M„e (+5548999181410)...
     [HORA] Agora: 27/07/2025 13:51 | Agendado: 27/07/2025 13:48
[13:51] Enviando mensagem para M„e (+5548999181410)...
Traceback (most recent call last):
  File "C:\IMPAR\enviar_whatsapp.py", line 67, in main
    subprocess.run(["python", CAMINHO_SCRIPT_ENVIO, telefone, mensagem], check=True)
    ~~~~~~~~~~~~~~^^^^^^^^^^^^^^^^^^^^^^^^^^^^^^^^^^^^^^^^^^^^^^^^^^^^^^^^^^^^^^^^^^
  File "C:\Users\ramos\AppData\Local\Programs\Python\Python313\Lib\subprocess.py", line 577, in run
    raise CalledProcessError(retcode, process.args,
                             output=stdout, stderr=stderr)
subprocess.CalledProcessError: Command '['python', 'C:/IMPAR/enviar_whatsapp.py', '+5548999181410', 'Feliz anivers·rio, M„e! \U0001f389']' returned non-zero exit status 1.

During handling of the above exception, another exception occurred:

Traceback (most recent call last):
  File "C:\IMPAR\enviar_whatsapp.py", line 78, in <module>
    main()
    ~~~~^^
  File "C:\IMPAR\enviar_whatsapp.py", line 71, in main
    print(f"[ERRO] Erro ao enviar para {telefone}: {e}")
    ~~~~~^^^^^^^^^^^^^^^^^^^^^^^^^^^^^^^^^^^^^^^^^^^^^^^
  File "C:\Users\ramos\AppData\Local\Programs\Python\Python313\Lib\encodings\cp1252.py", line 19, in encode
    return codecs.charmap_encode(input,self.errors,encoding_table)[0]
           ~~~~~~~~~~~~~~~~~~~~~^^^^^^^^^^^^^^^^^^^^^^^^^^^^^^^^^^
UnicodeEncodeError: 'charmap' codec can't encode character '\U0001f389' in position 137: character maps to <undefined>
[13:51:50] Iniciando envio pela planilha...
[13:51] Avaliando envio para M„e (+5548999181410)...
     [HORA] Agora: 27/07/2025 13:51 | Agendado: 27/07/2025 13:48
[13:51] Enviando mensagem para M„e (+5548999181410)...
Traceback (most recent call last):
  File "C:\IMPAR\enviar_whatsapp.py", line 67, in main
    subprocess.run(["python", CAMINHO_SCRIPT_ENVIO, telefone, mensagem], check=True)
    ~~~~~~~~~~~~~~^^^^^^^^^^^^^^^^^^^^^^^^^^^^^^^^^^^^^^^^^^^^^^^^^^^^^^^^^^^^^^^^^^
  File "C:\Users\ramos\AppData\Local\Programs\Python\Python313\Lib\subprocess.py", line 577, in run
    raise CalledProcessError(retcode, process.args,
                             output=stdout, stderr=stderr)
subprocess.CalledProcessError: Command '['python', 'C:/IMPAR/enviar_whatsapp.py', '+5548999181410', 'Feliz anivers·rio, M„e! \U0001f389']' returned non-zero exit status 1.

During handling of the above exception, another exception occurred:

Traceback (most recent call last):
  File "C:\IMPAR\enviar_whatsapp.py", line 78, in <module>
    main()
    ~~~~^^
  File "C:\IMPAR\enviar_whatsapp.py", line 71, in main
    print(f"[ERRO] Erro ao enviar para {telefone}: {e}")
    ~~~~~^^^^^^^^^^^^^^^^^^^^^^^^^^^^^^^^^^^^^^^^^^^^^^^
  File "C:\Users\ramos\AppData\Local\Programs\Python\Python313\Lib\encodings\cp1252.py", line 19, in encode
    return codecs.charmap_encode(input,self.errors,encoding_table)[0]
           ~~~~~~~~~~~~~~~~~~~~~^^^^^^^^^^^^^^^^^^^^^^^^^^^^^^^^^^
UnicodeEncodeError: 'charmap' codec can't encode character '\U0001f389' in position 137: character maps to <undefined>
[13:51:49] Iniciando envio pela planilha...
[13:51] Avaliando envio para M„e (+5548999181410)...
     [HORA] Agora: 27/07/2025 13:51 | Agendado: 27/07/2025 13:48
[13:51] Enviando mensagem para M„e (+5548999181410)...
Traceback (most recent call last):
  File "C:\IMPAR\enviar_whatsapp.py", line 67, in main
    subprocess.run(["python", CAMINHO_SCRIPT_ENVIO, telefone, mensagem], check=True)
    ~~~~~~~~~~~~~~^^^^^^^^^^^^^^^^^^^^^^^^^^^^^^^^^^^^^^^^^^^^^^^^^^^^^^^^^^^^^^^^^^
  File "C:\Users\ramos\AppData\Local\Programs\Python\Python313\Lib\subprocess.py", line 577, in run
    raise CalledProcessError(retcode, process.args,
                             output=stdout, stderr=stderr)
subprocess.CalledProcessError: Command '['python', 'C:/IMPAR/enviar_whatsapp.py', '+5548999181410', 'Feliz anivers·rio, M„e! \U0001f389']' returned non-zero exit status 1.

During handling of the above exception, another exception occurred:

Traceback (most recent call last):
  File "C:\IMPAR\enviar_whatsapp.py", line 78, in <module>
    main()
    ~~~~^^
  File "C:\IMPAR\enviar_whatsapp.py", line 71, in main
    print(f"[ERRO] Erro ao enviar para {telefone}: {e}")
    ~~~~~^^^^^^^^^^^^^^^^^^^^^^^^^^^^^^^^^^^^^^^^^^^^^^^
  File "C:\Users\ramos\AppData\Local\Programs\Python\Python313\Lib\encodings\cp1252.py", line 19, in encode
    return codecs.charmap_encode(input,self.errors,encoding_table)[0]
           ~~~~~~~~~~~~~~~~~~~~~^^^^^^^^^^^^^^^^^^^^^^^^^^^^^^^^^^
UnicodeEncodeError: 'charmap' codec can't encode character '\U0001f389' in position 137: character maps to <undefined>
[13:51:47] Iniciando envio pela planilha...
[13:51] Avaliando envio para M„e (+5548999181410)...
     [HORA] Agora: 27/07/2025 13:51 | Agendado: 27/07/2025 13:48
[13:51] Enviando mensagem para M„e (+5548999181410)...
Traceback (most recent call last):
  File "C:\IMPAR\enviar_whatsapp.py", line 67, in main
    subprocess.run(["python", CAMINHO_SCRIPT_ENVIO, telefone, mensagem], check=True)
    ~~~~~~~~~~~~~~^^^^^^^^^^^^^^^^^^^^^^^^^^^^^^^^^^^^^^^^^^^^^^^^^^^^^^^^^^^^^^^^^^
  File "C:\Users\ramos\AppData\Local\Programs\Python\Python313\Lib\subprocess.py", line 577, in run
    raise CalledProcessError(retcode, process.args,
                             output=stdout, stderr=stderr)
subprocess.CalledProcessError: Command '['python', 'C:/IMPAR/enviar_whatsapp.py', '+5548999181410', 'Feliz anivers·rio, M„e! \U0001f389']' returned non-zero exit status 1.

During handling of the above exception, another exception occurred:

Traceback (most recent call last):
  File "C:\IMPAR\enviar_whatsapp.py", line 78, in <module>
    main()
    ~~~~^^
  File "C:\IMPAR\enviar_whatsapp.py", line 71, in main
    print(f"[ERRO] Erro ao enviar para {telefone}: {e}")
    ~~~~~^^^^^^^^^^^^^^^^^^^^^^^^^^^^^^^^^^^^^^^^^^^^^^^
  File "C:\Users\ramos\AppData\Local\Programs\Python\Python313\Lib\encodings\cp1252.py", line 19, in encode
    return codecs.charmap_encode(input,self.errors,encoding_table)[0]
           ~~~~~~~~~~~~~~~~~~~~~^^^^^^^^^^^^^^^^^^^^^^^^^^^^^^^^^^
UnicodeEncodeError: 'charmap' codec can't encode character '\U0001f389' in position 137: character maps to <undefined>
[13:51:46] Iniciando envio pela planilha...
[13:51] Avaliando envio para M„e (+5548999181410)...
     [HORA] Agora: 27/07/2025 13:51 | Agendado: 27/07/2025 13:48
[13:51] Enviando mensagem para M„e (+5548999181410)...
Traceback (most recent call last):
  File "C:\IMPAR\enviar_whatsapp.py", line 67, in main
    subprocess.run(["python", CAMINHO_SCRIPT_ENVIO, telefone, mensagem], check=True)
    ~~~~~~~~~~~~~~^^^^^^^^^^^^^^^^^^^^^^^^^^^^^^^^^^^^^^^^^^^^^^^^^^^^^^^^^^^^^^^^^^
  File "C:\Users\ramos\AppData\Local\Programs\Python\Python313\Lib\subprocess.py", line 577, in run
    raise CalledProcessError(retcode, process.args,
                             output=stdout, stderr=stderr)
subprocess.CalledProcessError: Command '['python', 'C:/IMPAR/enviar_whatsapp.py', '+5548999181410', 'Feliz anivers·rio, M„e! \U0001f389']' returned non-zero exit status 1.

During handling of the above exception, another exception occurred:

Traceback (most recent call last):
  File "C:\IMPAR\enviar_whatsapp.py", line 78, in <module>
    main()
    ~~~~^^
  File "C:\IMPAR\enviar_whatsapp.py", line 71, in main
    print(f"[ERRO] Erro ao enviar para {telefone}: {e}")
    ~~~~~^^^^^^^^^^^^^^^^^^^^^^^^^^^^^^^^^^^^^^^^^^^^^^^
  File "C:\Users\ramos\AppData\Local\Programs\Python\Python313\Lib\encodings\cp1252.py", line 19, in encode
    return codecs.charmap_encode(input,self.errors,encoding_table)[0]
           ~~~~~~~~~~~~~~~~~~~~~^^^^^^^^^^^^^^^^^^^^^^^^^^^^^^^^^^
UnicodeEncodeError: 'charmap' codec can't encode character '\U0001f389' in position 137: character maps to <undefined>
[13:51:45] Iniciando envio pela planilha...
[13:51] Avaliando envio para M„e (+5548999181410)...
     [HORA] Agora: 27/07/2025 13:51 | Agendado: 27/07/2025 13:48
[13:51] Enviando mensagem para M„e (+5548999181410)...
Traceback (most recent call last):
  File "C:\IMPAR\enviar_whatsapp.py", line 67, in main
    subprocess.run(["python", CAMINHO_SCRIPT_ENVIO, telefone, mensagem], check=True)
    ~~~~~~~~~~~~~~^^^^^^^^^^^^^^^^^^^^^^^^^^^^^^^^^^^^^^^^^^^^^^^^^^^^^^^^^^^^^^^^^^
  File "C:\Users\ramos\AppData\Local\Programs\Python\Python313\Lib\subprocess.py", line 577, in run
    raise CalledProcessError(retcode, process.args,
                             output=stdout, stderr=stderr)
subprocess.CalledProcessError: Command '['python', 'C:/IMPAR/enviar_whatsapp.py', '+5548999181410', 'Feliz anivers·rio, M„e! \U0001f389']' returned non-zero exit status 1.

During handling of the above exception, another exception occurred:

Traceback (most recent call last):
  File "C:\IMPAR\enviar_whatsapp.py", line 78, in <module>
    main()
    ~~~~^^
  File "C:\IMPAR\enviar_whatsapp.py", line 71, in main
    print(f"[ERRO] Erro ao enviar para {telefone}: {e}")
    ~~~~~^^^^^^^^^^^^^^^^^^^^^^^^^^^^^^^^^^^^^^^^^^^^^^^
  File "C:\Users\ramos\AppData\Local\Programs\Python\Python313\Lib\encodings\cp1252.py", line 19, in encode
    return codecs.charmap_encode(input,self.errors,encoding_table)[0]
           ~~~~~~~~~~~~~~~~~~~~~^^^^^^^^^^^^^^^^^^^^^^^^^^^^^^^^^^
UnicodeEncodeError: 'charmap' codec can't encode character '\U0001f389' in position 137: character maps to <undefined>
[13:51:44] Iniciando envio pela planilha...
[13:51] Avaliando envio para M„e (+5548999181410)...
     [HORA] Agora: 27/07/2025 13:51 | Agendado: 27/07/2025 13:48
[13:51] Enviando mensagem para M„e (+5548999181410)...
Traceback (most recent call last):
  File "C:\IMPAR\enviar_whatsapp.py", line 67, in main
    subprocess.run(["python", CAMINHO_SCRIPT_ENVIO, telefone, mensagem], check=True)
    ~~~~~~~~~~~~~~^^^^^^^^^^^^^^^^^^^^^^^^^^^^^^^^^^^^^^^^^^^^^^^^^^^^^^^^^^^^^^^^^^
  File "C:\Users\ramos\AppData\Local\Programs\Python\Python313\Lib\subprocess.py", line 577, in run
    raise CalledProcessError(retcode, process.args,
                             output=stdout, stderr=stderr)
subprocess.CalledProcessError: Command '['python', 'C:/IMPAR/enviar_whatsapp.py', '+5548999181410', 'Feliz anivers·rio, M„e! \U0001f389']' returned non-zero exit status 1.

During handling of the above exception, another exception occurred:

Traceback (most recent call last):
  File "C:\IMPAR\enviar_whatsapp.py", line 78, in <module>
    main()
    ~~~~^^
  File "C:\IMPAR\enviar_whatsapp.py", line 71, in main
    print(f"[ERRO] Erro ao enviar para {telefone}: {e}")
    ~~~~~^^^^^^^^^^^^^^^^^^^^^^^^^^^^^^^^^^^^^^^^^^^^^^^
  File "C:\Users\ramos\AppData\Local\Programs\Python\Python313\Lib\encodings\cp1252.py", line 19, in encode
    return codecs.charmap_encode(input,self.errors,encoding_table)[0]
           ~~~~~~~~~~~~~~~~~~~~~^^^^^^^^^^^^^^^^^^^^^^^^^^^^^^^^^^
UnicodeEncodeError: 'charmap' codec can't encode character '\U0001f389' in position 137: character maps to <undefined>
[13:51:43] Iniciando envio pela planilha...
[13:51] Avaliando envio para M„e (+5548999181410)...
     [HORA] Agora: 27/07/2025 13:51 | Agendado: 27/07/2025 13:48
[13:51] Enviando mensagem para M„e (+5548999181410)...
Traceback (most recent call last):
  File "C:\IMPAR\enviar_whatsapp.py", line 67, in main
    subprocess.run(["python", CAMINHO_SCRIPT_ENVIO, telefone, mensagem], check=True)
    ~~~~~~~~~~~~~~^^^^^^^^^^^^^^^^^^^^^^^^^^^^^^^^^^^^^^^^^^^^^^^^^^^^^^^^^^^^^^^^^^
  File "C:\Users\ramos\AppData\Local\Programs\Python\Python313\Lib\subprocess.py", line 577, in run
    raise CalledProcessError(retcode, process.args,
                             output=stdout, stderr=stderr)
subprocess.CalledProcessError: Command '['python', 'C:/IMPAR/enviar_whatsapp.py', '+5548999181410', 'Feliz anivers·rio, M„e! \U0001f389']' returned non-zero exit status 1.

During handling of the above exception, another exception occurred:

Traceback (most recent call last):
  File "C:\IMPAR\enviar_whatsapp.py", line 78, in <module>
    main()
    ~~~~^^
  File "C:\IMPAR\enviar_whatsapp.py", line 71, in main
    print(f"[ERRO] Erro ao enviar para {telefone}: {e}")
    ~~~~~^^^^^^^^^^^^^^^^^^^^^^^^^^^^^^^^^^^^^^^^^^^^^^^
  File "C:\Users\ramos\AppData\Local\Programs\Python\Python313\Lib\encodings\cp1252.py", line 19, in encode
    return codecs.charmap_encode(input,self.errors,encoding_table)[0]
           ~~~~~~~~~~~~~~~~~~~~~^^^^^^^^^^^^^^^^^^^^^^^^^^^^^^^^^^
UnicodeEncodeError: 'charmap' codec can't encode character '\U0001f389' in position 137: character maps to <undefined>
[13:51:41] Iniciando envio pela planilha...
[13:51] Avaliando envio para M„e (+5548999181410)...
     [HORA] Agora: 27/07/2025 13:51 | Agendado: 27/07/2025 13:48
[13:51] Enviando mensagem para M„e (+5548999181410)...
Traceback (most recent call last):
  File "C:\IMPAR\enviar_whatsapp.py", line 67, in main
    subprocess.run(["python", CAMINHO_SCRIPT_ENVIO, telefone, mensagem], check=True)
    ~~~~~~~~~~~~~~^^^^^^^^^^^^^^^^^^^^^^^^^^^^^^^^^^^^^^^^^^^^^^^^^^^^^^^^^^^^^^^^^^
  File "C:\Users\ramos\AppData\Local\Programs\Python\Python313\Lib\subprocess.py", line 577, in run
    raise CalledProcessError(retcode, process.args,
                             output=stdout, stderr=stderr)
subprocess.CalledProcessError: Command '['python', 'C:/IMPAR/enviar_whatsapp.py', '+5548999181410', 'Feliz anivers·rio, M„e! \U0001f389']' returned non-zero exit status 1.

During handling of the above exception, another exception occurred:

Traceback (most recent call last):
  File "C:\IMPAR\enviar_whatsapp.py", line 78, in <module>
    main()
    ~~~~^^
  File "C:\IMPAR\enviar_whatsapp.py", line 71, in main
    print(f"[ERRO] Erro ao enviar para {telefone}: {e}")
    ~~~~~^^^^^^^^^^^^^^^^^^^^^^^^^^^^^^^^^^^^^^^^^^^^^^^
  File "C:\Users\ramos\AppData\Local\Programs\Python\Python313\Lib\encodings\cp1252.py", line 19, in encode
    return codecs.charmap_encode(input,self.errors,encoding_table)[0]
           ~~~~~~~~~~~~~~~~~~~~~^^^^^^^^^^^^^^^^^^^^^^^^^^^^^^^^^^
UnicodeEncodeError: 'charmap' codec can't encode character '\U0001f389' in position 137: character maps to <undefined>
[13:51:40] Iniciando envio pela planilha...
[13:51] Avaliando envio para M„e (+5548999181410)...
     [HORA] Agora: 27/07/2025 13:51 | Agendado: 27/07/2025 13:48
[13:51] Enviando mensagem para M„e (+5548999181410)...
Traceback (most recent call last):
  File "C:\IMPAR\enviar_whatsapp.py", line 67, in main
    subprocess.run(["python", CAMINHO_SCRIPT_ENVIO, telefone, mensagem], check=True)
    ~~~~~~~~~~~~~~^^^^^^^^^^^^^^^^^^^^^^^^^^^^^^^^^^^^^^^^^^^^^^^^^^^^^^^^^^^^^^^^^^
  File "C:\Users\ramos\AppData\Local\Programs\Python\Python313\Lib\subprocess.py", line 577, in run
    raise CalledProcessError(retcode, process.args,
                             output=stdout, stderr=stderr)
subprocess.CalledProcessError: Command '['python', 'C:/IMPAR/enviar_whatsapp.py', '+5548999181410', 'Feliz anivers·rio, M„e! \U0001f389']' returned non-zero exit status 1.

During handling of the above exception, another exception occurred:

Traceback (most recent call last):
  File "C:\IMPAR\enviar_whatsapp.py", line 78, in <module>
    main()
    ~~~~^^
  File "C:\IMPAR\enviar_whatsapp.py", line 71, in main
    print(f"[ERRO] Erro ao enviar para {telefone}: {e}")
    ~~~~~^^^^^^^^^^^^^^^^^^^^^^^^^^^^^^^^^^^^^^^^^^^^^^^
  File "C:\Users\ramos\AppData\Local\Programs\Python\Python313\Lib\encodings\cp1252.py", line 19, in encode
    return codecs.charmap_encode(input,self.errors,encoding_table)[0]
           ~~~~~~~~~~~~~~~~~~~~~^^^^^^^^^^^^^^^^^^^^^^^^^^^^^^^^^^
UnicodeEncodeError: 'charmap' codec can't encode character '\U0001f389' in position 137: character maps to <undefined>
[13:51:39] Iniciando envio pela planilha...
[13:51] Avaliando envio para M„e (+5548999181410)...
     [HORA] Agora: 27/07/2025 13:51 | Agendado: 27/07/2025 13:48
[13:51] Enviando mensagem para M„e (+5548999181410)...
Traceback (most recent call last):
  File "C:\IMPAR\enviar_whatsapp.py", line 67, in main
    subprocess.run(["python", CAMINHO_SCRIPT_ENVIO, telefone, mensagem], check=True)
    ~~~~~~~~~~~~~~^^^^^^^^^^^^^^^^^^^^^^^^^^^^^^^^^^^^^^^^^^^^^^^^^^^^^^^^^^^^^^^^^^
  File "C:\Users\ramos\AppData\Local\Programs\Python\Python313\Lib\subprocess.py", line 577, in run
    raise CalledProcessError(retcode, process.args,
                             output=stdout, stderr=stderr)
subprocess.CalledProcessError: Command '['python', 'C:/IMPAR/enviar_whatsapp.py', '+5548999181410', 'Feliz anivers·rio, M„e! \U0001f389']' returned non-zero exit status 1.

During handling of the above exception, another exception occurred:

Traceback (most recent call last):
  File "C:\IMPAR\enviar_whatsapp.py", line 78, in <module>
    main()
    ~~~~^^
  File "C:\IMPAR\enviar_whatsapp.py", line 71, in main
    print(f"[ERRO] Erro ao enviar para {telefone}: {e}")
    ~~~~~^^^^^^^^^^^^^^^^^^^^^^^^^^^^^^^^^^^^^^^^^^^^^^^
  File "C:\Users\ramos\AppData\Local\Programs\Python\Python313\Lib\encodings\cp1252.py", line 19, in encode
    return codecs.charmap_encode(input,self.errors,encoding_table)[0]
           ~~~~~~~~~~~~~~~~~~~~~^^^^^^^^^^^^^^^^^^^^^^^^^^^^^^^^^^
UnicodeEncodeError: 'charmap' codec can't encode character '\U0001f389' in position 137: character maps to <undefined>
[13:51:37] Iniciando envio pela planilha...
[13:51] Avaliando envio para M„e (+5548999181410)...
     [HORA] Agora: 27/07/2025 13:51 | Agendado: 27/07/2025 13:48
[13:51] Enviando mensagem para M„e (+5548999181410)...
Traceback (most recent call last):
  File "C:\IMPAR\enviar_whatsapp.py", line 67, in main
    subprocess.run(["python", CAMINHO_SCRIPT_ENVIO, telefone, mensagem], check=True)
    ~~~~~~~~~~~~~~^^^^^^^^^^^^^^^^^^^^^^^^^^^^^^^^^^^^^^^^^^^^^^^^^^^^^^^^^^^^^^^^^^
  File "C:\Users\ramos\AppData\Local\Programs\Python\Python313\Lib\subprocess.py", line 577, in run
    raise CalledProcessError(retcode, process.args,
                             output=stdout, stderr=stderr)
subprocess.CalledProcessError: Command '['python', 'C:/IMPAR/enviar_whatsapp.py', '+5548999181410', 'Feliz anivers·rio, M„e! \U0001f389']' returned non-zero exit status 1.

During handling of the above exception, another exception occurred:

Traceback (most recent call last):
  File "C:\IMPAR\enviar_whatsapp.py", line 78, in <module>
    main()
    ~~~~^^
  File "C:\IMPAR\enviar_whatsapp.py", line 71, in main
    print(f"[ERRO] Erro ao enviar para {telefone}: {e}")
    ~~~~~^^^^^^^^^^^^^^^^^^^^^^^^^^^^^^^^^^^^^^^^^^^^^^^
  File "C:\Users\ramos\AppData\Local\Programs\Python\Python313\Lib\encodings\cp1252.py", line 19, in encode
    return codecs.charmap_encode(input,self.errors,encoding_table)[0]
           ~~~~~~~~~~~~~~~~~~~~~^^^^^^^^^^^^^^^^^^^^^^^^^^^^^^^^^^
UnicodeEncodeError: 'charmap' codec can't encode character '\U0001f389' in position 137: character maps to <undefined>
[13:51:35] Iniciando envio pela planilha...
[13:51] Avaliando envio para M„e (+5548999181410)...
     [HORA] Agora: 27/07/2025 13:51 | Agendado: 27/07/2025 13:48
[13:51] Enviando mensagem para M„e (+5548999181410)...
Traceback (most recent call last):
  File "C:\IMPAR\enviar_whatsapp.py", line 67, in main
    subprocess.run(["python", CAMINHO_SCRIPT_ENVIO, telefone, mensagem], check=True)
    ~~~~~~~~~~~~~~^^^^^^^^^^^^^^^^^^^^^^^^^^^^^^^^^^^^^^^^^^^^^^^^^^^^^^^^^^^^^^^^^^
  File "C:\Users\ramos\AppData\Local\Programs\Python\Python313\Lib\subprocess.py", line 577, in run
    raise CalledProcessError(retcode, process.args,
                             output=stdout, stderr=stderr)
subprocess.CalledProcessError: Command '['python', 'C:/IMPAR/enviar_whatsapp.py', '+5548999181410', 'Feliz anivers·rio, M„e! \U0001f389']' returned non-zero exit status 1.

During handling of the above exception, another exception occurred:

Traceback (most recent call last):
  File "C:\IMPAR\enviar_whatsapp.py", line 78, in <module>
    main()
    ~~~~^^
  File "C:\IMPAR\enviar_whatsapp.py", line 71, in main
    print(f"[ERRO] Erro ao enviar para {telefone}: {e}")
    ~~~~~^^^^^^^^^^^^^^^^^^^^^^^^^^^^^^^^^^^^^^^^^^^^^^^
  File "C:\Users\ramos\AppData\Local\Programs\Python\Python313\Lib\encodings\cp1252.py", line 19, in encode
    return codecs.charmap_encode(input,self.errors,encoding_table)[0]
           ~~~~~~~~~~~~~~~~~~~~~^^^^^^^^^^^^^^^^^^^^^^^^^^^^^^^^^^
UnicodeEncodeError: 'charmap' codec can't encode character '\U0001f389' in position 137: character maps to <undefined>
[13:51:34] Iniciando envio pela planilha...
[13:51] Avaliando envio para M„e (+5548999181410)...
     [HORA] Agora: 27/07/2025 13:51 | Agendado: 27/07/2025 13:48
[13:51] Enviando mensagem para M„e (+5548999181410)...
Traceback (most recent call last):
  File "C:\IMPAR\enviar_whatsapp.py", line 67, in main
    subprocess.run(["python", CAMINHO_SCRIPT_ENVIO, telefone, mensagem], check=True)
    ~~~~~~~~~~~~~~^^^^^^^^^^^^^^^^^^^^^^^^^^^^^^^^^^^^^^^^^^^^^^^^^^^^^^^^^^^^^^^^^^
  File "C:\Users\ramos\AppData\Local\Programs\Python\Python313\Lib\subprocess.py", line 577, in run
    raise CalledProcessError(retcode, process.args,
                             output=stdout, stderr=stderr)
subprocess.CalledProcessError: Command '['python', 'C:/IMPAR/enviar_whatsapp.py', '+5548999181410', 'Feliz anivers·rio, M„e! \U0001f389']' returned non-zero exit status 1.

During handling of the above exception, another exception occurred:

Traceback (most recent call last):
  File "C:\IMPAR\enviar_whatsapp.py", line 78, in <module>
    main()
    ~~~~^^
  File "C:\IMPAR\enviar_whatsapp.py", line 71, in main
    print(f"[ERRO] Erro ao enviar para {telefone}: {e}")
    ~~~~~^^^^^^^^^^^^^^^^^^^^^^^^^^^^^^^^^^^^^^^^^^^^^^^
  File "C:\Users\ramos\AppData\Local\Programs\Python\Python313\Lib\encodings\cp1252.py", line 19, in encode
    return codecs.charmap_encode(input,self.errors,encoding_table)[0]
           ~~~~~~~~~~~~~~~~~~~~~^^^^^^^^^^^^^^^^^^^^^^^^^^^^^^^^^^
UnicodeEncodeError: 'charmap' codec can't encode character '\U0001f389' in position 137: character maps to <undefined>
[13:51:33] Iniciando envio pela planilha...
[13:51] Avaliando envio para M„e (+5548999181410)...
     [HORA] Agora: 27/07/2025 13:51 | Agendado: 27/07/2025 13:48
[13:51] Enviando mensagem para M„e (+5548999181410)...
Traceback (most recent call last):
  File "C:\IMPAR\enviar_whatsapp.py", line 67, in main
    subprocess.run(["python", CAMINHO_SCRIPT_ENVIO, telefone, mensagem], check=True)
    ~~~~~~~~~~~~~~^^^^^^^^^^^^^^^^^^^^^^^^^^^^^^^^^^^^^^^^^^^^^^^^^^^^^^^^^^^^^^^^^^
  File "C:\Users\ramos\AppData\Local\Programs\Python\Python313\Lib\subprocess.py", line 577, in run
    raise CalledProcessError(retcode, process.args,
                             output=stdout, stderr=stderr)
subprocess.CalledProcessError: Command '['python', 'C:/IMPAR/enviar_whatsapp.py', '+5548999181410', 'Feliz anivers·rio, M„e! \U0001f389']' returned non-zero exit status 1.

During handling of the above exception, another exception occurred:

Traceback (most recent call last):
  File "C:\IMPAR\enviar_whatsapp.py", line 78, in <module>
    main()
    ~~~~^^
  File "C:\IMPAR\enviar_whatsapp.py", line 71, in main
    print(f"[ERRO] Erro ao enviar para {telefone}: {e}")
    ~~~~~^^^^^^^^^^^^^^^^^^^^^^^^^^^^^^^^^^^^^^^^^^^^^^^
  File "C:\Users\ramos\AppData\Local\Programs\Python\Python313\Lib\encodings\cp1252.py", line 19, in encode
    return codecs.charmap_encode(input,self.errors,encoding_table)[0]
           ~~~~~~~~~~~~~~~~~~~~~^^^^^^^^^^^^^^^^^^^^^^^^^^^^^^^^^^
UnicodeEncodeError: 'charmap' codec can't encode character '\U0001f389' in position 137: character maps to <undefined>
[13:51:29] Iniciando envio pela planilha...
[13:51] Avaliando envio para M„e (+5548999181410)...
     [HORA] Agora: 27/07/2025 13:51 | Agendado: 27/07/2025 13:48
[13:51] Enviando mensagem para M„e (+5548999181410)...
Traceback (most recent call last):
  File "C:\IMPAR\enviar_whatsapp.py", line 67, in main
    subprocess.run(["python", CAMINHO_SCRIPT_ENVIO, telefone, mensagem], check=True)
    ~~~~~~~~~~~~~~^^^^^^^^^^^^^^^^^^^^^^^^^^^^^^^^^^^^^^^^^^^^^^^^^^^^^^^^^^^^^^^^^^
  File "C:\Users\ramos\AppData\Local\Programs\Python\Python313\Lib\subprocess.py", line 577, in run
    raise CalledProcessError(retcode, process.args,
                             output=stdout, stderr=stderr)
subprocess.CalledProcessError: Command '['python', 'C:/IMPAR/enviar_whatsapp.py', '+5548999181410', 'Feliz anivers·rio, M„e! \U0001f389']' returned non-zero exit status 1.

During handling of the above exception, another exception occurred:

Traceback (most recent call last):
  File "C:\IMPAR\enviar_whatsapp.py", line 78, in <module>
    main()
    ~~~~^^
  File "C:\IMPAR\enviar_whatsapp.py", line 71, in main
    print(f"[ERRO] Erro ao enviar para {telefone}: {e}")
    ~~~~~^^^^^^^^^^^^^^^^^^^^^^^^^^^^^^^^^^^^^^^^^^^^^^^
  File "C:\Users\ramos\AppData\Local\Programs\Python\Python313\Lib\encodings\cp1252.py", line 19, in encode
    return codecs.charmap_encode(input,self.errors,encoding_table)[0]
           ~~~~~~~~~~~~~~~~~~~~~^^^^^^^^^^^^^^^^^^^^^^^^^^^^^^^^^^
UnicodeEncodeError: 'charmap' codec can't encode character '\U0001f389' in position 137: character maps to <undefined>
[13:51:26] Iniciando envio pela planilha...
[13:51] Avaliando envio para M„e (+5548999181410)...
     [HORA] Agora: 27/07/2025 13:51 | Agendado: 27/07/2025 13:48
[13:51] Enviando mensagem para M„e (+5548999181410)...
Traceback (most recent call last):
  File "C:\IMPAR\enviar_whatsapp.py", line 67, in main
    subprocess.run(["python", CAMINHO_SCRIPT_ENVIO, telefone, mensagem], check=True)
    ~~~~~~~~~~~~~~^^^^^^^^^^^^^^^^^^^^^^^^^^^^^^^^^^^^^^^^^^^^^^^^^^^^^^^^^^^^^^^^^^
  File "C:\Users\ramos\AppData\Local\Programs\Python\Python313\Lib\subprocess.py", line 577, in run
    raise CalledProcessError(retcode, process.args,
                             output=stdout, stderr=stderr)
subprocess.CalledProcessError: Command '['python', 'C:/IMPAR/enviar_whatsapp.py', '+5548999181410', 'Feliz anivers·rio, M„e! \U0001f389']' returned non-zero exit status 1.

During handling of the above exception, another exception occurred:

Traceback (most recent call last):
  File "C:\IMPAR\enviar_whatsapp.py", line 78, in <module>
    main()
    ~~~~^^
  File "C:\IMPAR\enviar_whatsapp.py", line 71, in main
    print(f"[ERRO] Erro ao enviar para {telefone}: {e}")
    ~~~~~^^^^^^^^^^^^^^^^^^^^^^^^^^^^^^^^^^^^^^^^^^^^^^^
  File "C:\Users\ramos\AppData\Local\Programs\Python\Python313\Lib\encodings\cp1252.py", line 19, in encode
    return codecs.charmap_encode(input,self.errors,encoding_table)[0]
           ~~~~~~~~~~~~~~~~~~~~~^^^^^^^^^^^^^^^^^^^^^^^^^^^^^^^^^^
UnicodeEncodeError: 'charmap' codec can't encode character '\U0001f389' in position 137: character maps to <undefined>
[13:51:26] Iniciando envio pela planilha...
[13:51] Avaliando envio para M„e (+5548999181410)...
     [HORA] Agora: 27/07/2025 13:51 | Agendado: 27/07/2025 13:48
[13:51] Enviando mensagem para M„e (+5548999181410)...
Traceback (most recent call last):
  File "C:\IMPAR\enviar_whatsapp.py", line 67, in main
    subprocess.run(["python", CAMINHO_SCRIPT_ENVIO, telefone, mensagem], check=True)
    ~~~~~~~~~~~~~~^^^^^^^^^^^^^^^^^^^^^^^^^^^^^^^^^^^^^^^^^^^^^^^^^^^^^^^^^^^^^^^^^^
  File "C:\Users\ramos\AppData\Local\Programs\Python\Python313\Lib\subprocess.py", line 577, in run
    raise CalledProcessError(retcode, process.args,
                             output=stdout, stderr=stderr)
subprocess.CalledProcessError: Command '['python', 'C:/IMPAR/enviar_whatsapp.py', '+5548999181410', 'Feliz anivers·rio, M„e! \U0001f389']' returned non-zero exit status 1.

During handling of the above exception, another exception occurred:

Traceback (most recent call last):
  File "C:\IMPAR\enviar_whatsapp.py", line 78, in <module>
    main()
    ~~~~^^
  File "C:\IMPAR\enviar_whatsapp.py", line 71, in main
    print(f"[ERRO] Erro ao enviar para {telefone}: {e}")
    ~~~~~^^^^^^^^^^^^^^^^^^^^^^^^^^^^^^^^^^^^^^^^^^^^^^^
  File "C:\Users\ramos\AppData\Local\Programs\Python\Python313\Lib\encodings\cp1252.py", line 19, in encode
    return codecs.charmap_encode(input,self.errors,encoding_table)[0]
           ~~~~~~~~~~~~~~~~~~~~~^^^^^^^^^^^^^^^^^^^^^^^^^^^^^^^^^^
UnicodeEncodeError: 'charmap' codec can't encode character '\U0001f389' in position 137: character maps to <undefined>
[13:51:24] Iniciando envio pela planilha...
[13:51] Avaliando envio para M„e (+5548999181410)...
     [HORA] Agora: 27/07/2025 13:51 | Agendado: 27/07/2025 13:48
[13:51] Enviando mensagem para M„e (+5548999181410)...
Traceback (most recent call last):
  File "C:\IMPAR\enviar_whatsapp.py", line 67, in main
    subprocess.run(["python", CAMINHO_SCRIPT_ENVIO, telefone, mensagem], check=True)
    ~~~~~~~~~~~~~~^^^^^^^^^^^^^^^^^^^^^^^^^^^^^^^^^^^^^^^^^^^^^^^^^^^^^^^^^^^^^^^^^^
  File "C:\Users\ramos\AppData\Local\Programs\Python\Python313\Lib\subprocess.py", line 577, in run
    raise CalledProcessError(retcode, process.args,
                             output=stdout, stderr=stderr)
subprocess.CalledProcessError: Command '['python', 'C:/IMPAR/enviar_whatsapp.py', '+5548999181410', 'Feliz anivers·rio, M„e! \U0001f389']' returned non-zero exit status 1.

During handling of the above exception, another exception occurred:

Traceback (most recent call last):
  File "C:\IMPAR\enviar_whatsapp.py", line 78, in <module>
    main()
    ~~~~^^
  File "C:\IMPAR\enviar_whatsapp.py", line 71, in main
    print(f"[ERRO] Erro ao enviar para {telefone}: {e}")
    ~~~~~^^^^^^^^^^^^^^^^^^^^^^^^^^^^^^^^^^^^^^^^^^^^^^^
  File "C:\Users\ramos\AppData\Local\Programs\Python\Python313\Lib\encodings\cp1252.py", line 19, in encode
    return codecs.charmap_encode(input,self.errors,encoding_table)[0]
           ~~~~~~~~~~~~~~~~~~~~~^^^^^^^^^^^^^^^^^^^^^^^^^^^^^^^^^^
UnicodeEncodeError: 'charmap' codec can't encode character '\U0001f389' in position 137: character maps to <undefined>
[13:51:23] Iniciando envio pela planilha...
[13:51] Avaliando envio para M„e (+5548999181410)...
     [HORA] Agora: 27/07/2025 13:51 | Agendado: 27/07/2025 13:48
[13:51] Enviando mensagem para M„e (+5548999181410)...
Traceback (most recent call last):
  File "C:\IMPAR\enviar_whatsapp.py", line 67, in main
    subprocess.run(["python", CAMINHO_SCRIPT_ENVIO, telefone, mensagem], check=True)
    ~~~~~~~~~~~~~~^^^^^^^^^^^^^^^^^^^^^^^^^^^^^^^^^^^^^^^^^^^^^^^^^^^^^^^^^^^^^^^^^^
  File "C:\Users\ramos\AppData\Local\Programs\Python\Python313\Lib\subprocess.py", line 577, in run
    raise CalledProcessError(retcode, process.args,
                             output=stdout, stderr=stderr)
subprocess.CalledProcessError: Command '['python', 'C:/IMPAR/enviar_whatsapp.py', '+5548999181410', 'Feliz anivers·rio, M„e! \U0001f389']' returned non-zero exit status 1.

During handling of the above exception, another exception occurred:

Traceback (most recent call last):
  File "C:\IMPAR\enviar_whatsapp.py", line 78, in <module>
    main()
    ~~~~^^
  File "C:\IMPAR\enviar_whatsapp.py", line 71, in main
    print(f"[ERRO] Erro ao enviar para {telefone}: {e}")
    ~~~~~^^^^^^^^^^^^^^^^^^^^^^^^^^^^^^^^^^^^^^^^^^^^^^^
  File "C:\Users\ramos\AppData\Local\Programs\Python\Python313\Lib\encodings\cp1252.py", line 19, in encode
    return codecs.charmap_encode(input,self.errors,encoding_table)[0]
           ~~~~~~~~~~~~~~~~~~~~~^^^^^^^^^^^^^^^^^^^^^^^^^^^^^^^^^^
UnicodeEncodeError: 'charmap' codec can't encode character '\U0001f389' in position 137: character maps to <undefined>
[13:51:21] Iniciando envio pela planilha...
[13:51] Avaliando envio para M„e (+5548999181410)...
     [HORA] Agora: 27/07/2025 13:51 | Agendado: 27/07/2025 13:48
[13:51] Enviando mensagem para M„e (+5548999181410)...
Traceback (most recent call last):
  File "C:\IMPAR\enviar_whatsapp.py", line 67, in main
    subprocess.run(["python", CAMINHO_SCRIPT_ENVIO, telefone, mensagem], check=True)
    ~~~~~~~~~~~~~~^^^^^^^^^^^^^^^^^^^^^^^^^^^^^^^^^^^^^^^^^^^^^^^^^^^^^^^^^^^^^^^^^^
  File "C:\Users\ramos\AppData\Local\Programs\Python\Python313\Lib\subprocess.py", line 577, in run
    raise CalledProcessError(retcode, process.args,
                             output=stdout, stderr=stderr)
subprocess.CalledProcessError: Command '['python', 'C:/IMPAR/enviar_whatsapp.py', '+5548999181410', 'Feliz anivers·rio, M„e! \U0001f389']' returned non-zero exit status 1.

During handling of the above exception, another exception occurred:

Traceback (most recent call last):
  File "C:\IMPAR\enviar_whatsapp.py", line 78, in <module>
    main()
    ~~~~^^
  File "C:\IMPAR\enviar_whatsapp.py", line 71, in main
    print(f"[ERRO] Erro ao enviar para {telefone}: {e}")
    ~~~~~^^^^^^^^^^^^^^^^^^^^^^^^^^^^^^^^^^^^^^^^^^^^^^^
  File "C:\Users\ramos\AppData\Local\Programs\Python\Python313\Lib\encodings\cp1252.py", line 19, in encode
    return codecs.charmap_encode(input,self.errors,encoding_table)[0]
           ~~~~~~~~~~~~~~~~~~~~~^^^^^^^^^^^^^^^^^^^^^^^^^^^^^^^^^^
UnicodeEncodeError: 'charmap' codec can't encode character '\U0001f389' in position 137: character maps to <undefined>
[13:51:20] Iniciando envio pela planilha...
[13:51] Avaliando envio para M„e (+5548999181410)...
     [HORA] Agora: 27/07/2025 13:51 | Agendado: 27/07/2025 13:48
[13:51] Enviando mensagem para M„e (+5548999181410)...
Traceback (most recent call last):
  File "C:\IMPAR\enviar_whatsapp.py", line 67, in main
    subprocess.run(["python", CAMINHO_SCRIPT_ENVIO, telefone, mensagem], check=True)
    ~~~~~~~~~~~~~~^^^^^^^^^^^^^^^^^^^^^^^^^^^^^^^^^^^^^^^^^^^^^^^^^^^^^^^^^^^^^^^^^^
  File "C:\Users\ramos\AppData\Local\Programs\Python\Python313\Lib\subprocess.py", line 577, in run
    raise CalledProcessError(retcode, process.args,
                             output=stdout, stderr=stderr)
subprocess.CalledProcessError: Command '['python', 'C:/IMPAR/enviar_whatsapp.py', '+5548999181410', 'Feliz anivers·rio, M„e! \U0001f389']' returned non-zero exit status 1.

During handling of the above exception, another exception occurred:

Traceback (most recent call last):
  File "C:\IMPAR\enviar_whatsapp.py", line 78, in <module>
    main()
    ~~~~^^
  File "C:\IMPAR\enviar_whatsapp.py", line 71, in main
    print(f"[ERRO] Erro ao enviar para {telefone}: {e}")
    ~~~~~^^^^^^^^^^^^^^^^^^^^^^^^^^^^^^^^^^^^^^^^^^^^^^^
  File "C:\Users\ramos\AppData\Local\Programs\Python\Python313\Lib\encodings\cp1252.py", line 19, in encode
    return codecs.charmap_encode(input,self.errors,encoding_table)[0]
           ~~~~~~~~~~~~~~~~~~~~~^^^^^^^^^^^^^^^^^^^^^^^^^^^^^^^^^^
UnicodeEncodeError: 'charmap' codec can't encode character '\U0001f389' in position 137: character maps to <undefined>
[13:51:18] Iniciando envio pela planilha...
[13:51] Avaliando envio para M„e (+5548999181410)...
     [HORA] Agora: 27/07/2025 13:51 | Agendado: 27/07/2025 13:48
[13:51] Enviando mensagem para M„e (+5548999181410)...
Traceback (most recent call last):
  File "C:\IMPAR\enviar_whatsapp.py", line 67, in main
    subprocess.run(["python", CAMINHO_SCRIPT_ENVIO, telefone, mensagem], check=True)
    ~~~~~~~~~~~~~~^^^^^^^^^^^^^^^^^^^^^^^^^^^^^^^^^^^^^^^^^^^^^^^^^^^^^^^^^^^^^^^^^^
  File "C:\Users\ramos\AppData\Local\Programs\Python\Python313\Lib\subprocess.py", line 577, in run
    raise CalledProcessError(retcode, process.args,
                             output=stdout, stderr=stderr)
subprocess.CalledProcessError: Command '['python', 'C:/IMPAR/enviar_whatsapp.py', '+5548999181410', 'Feliz anivers·rio, M„e! \U0001f389']' returned non-zero exit status 1.

During handling of the above exception, another exception occurred:

Traceback (most recent call last):
  File "C:\IMPAR\enviar_whatsapp.py", line 78, in <module>
    main()
    ~~~~^^
  File "C:\IMPAR\enviar_whatsapp.py", line 71, in main
    print(f"[ERRO] Erro ao enviar para {telefone}: {e}")
    ~~~~~^^^^^^^^^^^^^^^^^^^^^^^^^^^^^^^^^^^^^^^^^^^^^^^
  File "C:\Users\ramos\AppData\Local\Programs\Python\Python313\Lib\encodings\cp1252.py", line 19, in encode
    return codecs.charmap_encode(input,self.errors,encoding_table)[0]
           ~~~~~~~~~~~~~~~~~~~~~^^^^^^^^^^^^^^^^^^^^^^^^^^^^^^^^^^
UnicodeEncodeError: 'charmap' codec can't encode character '\U0001f389' in position 137: character maps to <undefined>
[13:51:16] Iniciando envio pela planilha...
[13:51] Avaliando envio para M„e (+5548999181410)...
     [HORA] Agora: 27/07/2025 13:51 | Agendado: 27/07/2025 13:48
[13:51] Enviando mensagem para M„e (+5548999181410)...
Traceback (most recent call last):
  File "C:\IMPAR\enviar_whatsapp.py", line 67, in main
    subprocess.run(["python", CAMINHO_SCRIPT_ENVIO, telefone, mensagem], check=True)
    ~~~~~~~~~~~~~~^^^^^^^^^^^^^^^^^^^^^^^^^^^^^^^^^^^^^^^^^^^^^^^^^^^^^^^^^^^^^^^^^^
  File "C:\Users\ramos\AppData\Local\Programs\Python\Python313\Lib\subprocess.py", line 577, in run
    raise CalledProcessError(retcode, process.args,
                             output=stdout, stderr=stderr)
subprocess.CalledProcessError: Command '['python', 'C:/IMPAR/enviar_whatsapp.py', '+5548999181410', 'Feliz anivers·rio, M„e! \U0001f389']' returned non-zero exit status 1.

During handling of the above exception, another exception occurred:

Traceback (most recent call last):
  File "C:\IMPAR\enviar_whatsapp.py", line 78, in <module>
    main()
    ~~~~^^
  File "C:\IMPAR\enviar_whatsapp.py", line 71, in main
    print(f"[ERRO] Erro ao enviar para {telefone}: {e}")
    ~~~~~^^^^^^^^^^^^^^^^^^^^^^^^^^^^^^^^^^^^^^^^^^^^^^^
  File "C:\Users\ramos\AppData\Local\Programs\Python\Python313\Lib\encodings\cp1252.py", line 19, in encode
    return codecs.charmap_encode(input,self.errors,encoding_table)[0]
           ~~~~~~~~~~~~~~~~~~~~~^^^^^^^^^^^^^^^^^^^^^^^^^^^^^^^^^^
UnicodeEncodeError: 'charmap' codec can't encode character '\U0001f389' in position 137: character maps to <undefined>
[13:51:15] Iniciando envio pela planilha...
[13:51] Avaliando envio para M„e (+5548999181410)...
     [HORA] Agora: 27/07/2025 13:51 | Agendado: 27/07/2025 13:48
[13:51] Enviando mensagem para M„e (+5548999181410)...
Traceback (most recent call last):
  File "C:\IMPAR\enviar_whatsapp.py", line 67, in main
    subprocess.run(["python", CAMINHO_SCRIPT_ENVIO, telefone, mensagem], check=True)
    ~~~~~~~~~~~~~~^^^^^^^^^^^^^^^^^^^^^^^^^^^^^^^^^^^^^^^^^^^^^^^^^^^^^^^^^^^^^^^^^^
  File "C:\Users\ramos\AppData\Local\Programs\Python\Python313\Lib\subprocess.py", line 577, in run
    raise CalledProcessError(retcode, process.args,
                             output=stdout, stderr=stderr)
subprocess.CalledProcessError: Command '['python', 'C:/IMPAR/enviar_whatsapp.py', '+5548999181410', 'Feliz anivers·rio, M„e! \U0001f389']' returned non-zero exit status 1.

During handling of the above exception, another exception occurred:

Traceback (most recent call last):
  File "C:\IMPAR\enviar_whatsapp.py", line 78, in <module>
    main()
    ~~~~^^
  File "C:\IMPAR\enviar_whatsapp.py", line 71, in main
    print(f"[ERRO] Erro ao enviar para {telefone}: {e}")
    ~~~~~^^^^^^^^^^^^^^^^^^^^^^^^^^^^^^^^^^^^^^^^^^^^^^^
  File "C:\Users\ramos\AppData\Local\Programs\Python\Python313\Lib\encodings\cp1252.py", line 19, in encode
    return codecs.charmap_encode(input,self.errors,encoding_table)[0]
           ~~~~~~~~~~~~~~~~~~~~~^^^^^^^^^^^^^^^^^^^^^^^^^^^^^^^^^^
UnicodeEncodeError: 'charmap' codec can't encode character '\U0001f389' in position 137: character maps to <undefined>
[13:51:13] Iniciando envio pela planilha...
[13:51] Avaliando envio para M„e (+5548999181410)...
     [HORA] Agora: 27/07/2025 13:51 | Agendado: 27/07/2025 13:48
[13:51] Enviando mensagem para M„e (+5548999181410)...
Traceback (most recent call last):
  File "C:\IMPAR\enviar_whatsapp.py", line 67, in main
    subprocess.run(["python", CAMINHO_SCRIPT_ENVIO, telefone, mensagem], check=True)
    ~~~~~~~~~~~~~~^^^^^^^^^^^^^^^^^^^^^^^^^^^^^^^^^^^^^^^^^^^^^^^^^^^^^^^^^^^^^^^^^^
  File "C:\Users\ramos\AppData\Local\Programs\Python\Python313\Lib\subprocess.py", line 577, in run
    raise CalledProcessError(retcode, process.args,
                             output=stdout, stderr=stderr)
subprocess.CalledProcessError: Command '['python', 'C:/IMPAR/enviar_whatsapp.py', '+5548999181410', 'Feliz anivers·rio, M„e! \U0001f389']' returned non-zero exit status 1.

During handling of the above exception, another exception occurred:

Traceback (most recent call last):
  File "C:\IMPAR\enviar_whatsapp.py", line 78, in <module>
    main()
    ~~~~^^
  File "C:\IMPAR\enviar_whatsapp.py", line 71, in main
    print(f"[ERRO] Erro ao enviar para {telefone}: {e}")
    ~~~~~^^^^^^^^^^^^^^^^^^^^^^^^^^^^^^^^^^^^^^^^^^^^^^^
  File "C:\Users\ramos\AppData\Local\Programs\Python\Python313\Lib\encodings\cp1252.py", line 19, in encode
    return codecs.charmap_encode(input,self.errors,encoding_table)[0]
           ~~~~~~~~~~~~~~~~~~~~~^^^^^^^^^^^^^^^^^^^^^^^^^^^^^^^^^^
UnicodeEncodeError: 'charmap' codec can't encode character '\U0001f389' in position 137: character maps to <undefined>
[13:51:11] Iniciando envio pela planilha...
[13:51] Avaliando envio para M„e (+5548999181410)...
     [HORA] Agora: 27/07/2025 13:51 | Agendado: 27/07/2025 13:48
[13:51] Enviando mensagem para M„e (+5548999181410)...
Traceback (most recent call last):
  File "C:\IMPAR\enviar_whatsapp.py", line 67, in main
    subprocess.run(["python", CAMINHO_SCRIPT_ENVIO, telefone, mensagem], check=True)
    ~~~~~~~~~~~~~~^^^^^^^^^^^^^^^^^^^^^^^^^^^^^^^^^^^^^^^^^^^^^^^^^^^^^^^^^^^^^^^^^^
  File "C:\Users\ramos\AppData\Local\Programs\Python\Python313\Lib\subprocess.py", line 577, in run
    raise CalledProcessError(retcode, process.args,
                             output=stdout, stderr=stderr)
subprocess.CalledProcessError: Command '['python', 'C:/IMPAR/enviar_whatsapp.py', '+5548999181410', 'Feliz anivers·rio, M„e! \U0001f389']' returned non-zero exit status 1.

During handling of the above exception, another exception occurred:

Traceback (most recent call last):
  File "C:\IMPAR\enviar_whatsapp.py", line 78, in <module>
    main()
    ~~~~^^
  File "C:\IMPAR\enviar_whatsapp.py", line 71, in main
    print(f"[ERRO] Erro ao enviar para {telefone}: {e}")
    ~~~~~^^^^^^^^^^^^^^^^^^^^^^^^^^^^^^^^^^^^^^^^^^^^^^^
  File "C:\Users\ramos\AppData\Local\Programs\Python\Python313\Lib\encodings\cp1252.py", line 19, in encode
    return codecs.charmap_encode(input,self.errors,encoding_table)[0]
           ~~~~~~~~~~~~~~~~~~~~~^^^^^^^^^^^^^^^^^^^^^^^^^^^^^^^^^^
UnicodeEncodeError: 'charmap' codec can't encode character '\U0001f389' in position 137: character maps to <undefined>
[13:51:10] Iniciando envio pela planilha...
[13:51] Avaliando envio para M„e (+5548999181410)...
     [HORA] Agora: 27/07/2025 13:51 | Agendado: 27/07/2025 13:48
[13:51] Enviando mensagem para M„e (+5548999181410)...
Traceback (most recent call last):
  File "C:\IMPAR\enviar_whatsapp.py", line 67, in main
    subprocess.run(["python", CAMINHO_SCRIPT_ENVIO, telefone, mensagem], check=True)
    ~~~~~~~~~~~~~~^^^^^^^^^^^^^^^^^^^^^^^^^^^^^^^^^^^^^^^^^^^^^^^^^^^^^^^^^^^^^^^^^^
  File "C:\Users\ramos\AppData\Local\Programs\Python\Python313\Lib\subprocess.py", line 577, in run
    raise CalledProcessError(retcode, process.args,
                             output=stdout, stderr=stderr)
subprocess.CalledProcessError: Command '['python', 'C:/IMPAR/enviar_whatsapp.py', '+5548999181410', 'Feliz anivers·rio, M„e! \U0001f389']' returned non-zero exit status 1.

During handling of the above exception, another exception occurred:

Traceback (most recent call last):
  File "C:\IMPAR\enviar_whatsapp.py", line 78, in <module>
    main()
    ~~~~^^
  File "C:\IMPAR\enviar_whatsapp.py", line 71, in main
    print(f"[ERRO] Erro ao enviar para {telefone}: {e}")
    ~~~~~^^^^^^^^^^^^^^^^^^^^^^^^^^^^^^^^^^^^^^^^^^^^^^^
  File "C:\Users\ramos\AppData\Local\Programs\Python\Python313\Lib\encodings\cp1252.py", line 19, in encode
    return codecs.charmap_encode(input,self.errors,encoding_table)[0]
           ~~~~~~~~~~~~~~~~~~~~~^^^^^^^^^^^^^^^^^^^^^^^^^^^^^^^^^^
UnicodeEncodeError: 'charmap' codec can't encode character '\U0001f389' in position 137: character maps to <undefined>
[13:51:09] Iniciando envio pela planilha...
[13:51] Avaliando envio para M„e (+5548999181410)...
     [HORA] Agora: 27/07/2025 13:51 | Agendado: 27/07/2025 13:48
[13:51] Enviando mensagem para M„e (+5548999181410)...
Traceback (most recent call last):
  File "C:\IMPAR\enviar_whatsapp.py", line 67, in main
    subprocess.run(["python", CAMINHO_SCRIPT_ENVIO, telefone, mensagem], check=True)
    ~~~~~~~~~~~~~~^^^^^^^^^^^^^^^^^^^^^^^^^^^^^^^^^^^^^^^^^^^^^^^^^^^^^^^^^^^^^^^^^^
  File "C:\Users\ramos\AppData\Local\Programs\Python\Python313\Lib\subprocess.py", line 577, in run
    raise CalledProcessError(retcode, process.args,
                             output=stdout, stderr=stderr)
subprocess.CalledProcessError: Command '['python', 'C:/IMPAR/enviar_whatsapp.py', '+5548999181410', 'Feliz anivers·rio, M„e! \U0001f389']' returned non-zero exit status 1.

During handling of the above exception, another exception occurred:

Traceback (most recent call last):
  File "C:\IMPAR\enviar_whatsapp.py", line 78, in <module>
    main()
    ~~~~^^
  File "C:\IMPAR\enviar_whatsapp.py", line 71, in main
    print(f"[ERRO] Erro ao enviar para {telefone}: {e}")
    ~~~~~^^^^^^^^^^^^^^^^^^^^^^^^^^^^^^^^^^^^^^^^^^^^^^^
  File "C:\Users\ramos\AppData\Local\Programs\Python\Python313\Lib\encodings\cp1252.py", line 19, in encode
    return codecs.charmap_encode(input,self.errors,encoding_table)[0]
           ~~~~~~~~~~~~~~~~~~~~~^^^^^^^^^^^^^^^^^^^^^^^^^^^^^^^^^^
UnicodeEncodeError: 'charmap' codec can't encode character '\U0001f389' in position 137: character maps to <undefined>
[13:51:06] Iniciando envio pela planilha...
[13:51] Avaliando envio para M„e (+5548999181410)...
     [HORA] Agora: 27/07/2025 13:51 | Agendado: 27/07/2025 13:48
[13:51] Enviando mensagem para M„e (+5548999181410)...
Traceback (most recent call last):
  File "C:\IMPAR\enviar_whatsapp.py", line 67, in main
    subprocess.run(["python", CAMINHO_SCRIPT_ENVIO, telefone, mensagem], check=True)
    ~~~~~~~~~~~~~~^^^^^^^^^^^^^^^^^^^^^^^^^^^^^^^^^^^^^^^^^^^^^^^^^^^^^^^^^^^^^^^^^^
  File "C:\Users\ramos\AppData\Local\Programs\Python\Python313\Lib\subprocess.py", line 577, in run
    raise CalledProcessError(retcode, process.args,
                             output=stdout, stderr=stderr)
subprocess.CalledProcessError: Command '['python', 'C:/IMPAR/enviar_whatsapp.py', '+5548999181410', 'Feliz anivers·rio, M„e! \U0001f389']' returned non-zero exit status 1.

During handling of the above exception, another exception occurred:

Traceback (most recent call last):
  File "C:\IMPAR\enviar_whatsapp.py", line 78, in <module>
    main()
    ~~~~^^
  File "C:\IMPAR\enviar_whatsapp.py", line 71, in main
    print(f"[ERRO] Erro ao enviar para {telefone}: {e}")
    ~~~~~^^^^^^^^^^^^^^^^^^^^^^^^^^^^^^^^^^^^^^^^^^^^^^^
  File "C:\Users\ramos\AppData\Local\Programs\Python\Python313\Lib\encodings\cp1252.py", line 19, in encode
    return codecs.charmap_encode(input,self.errors,encoding_table)[0]
           ~~~~~~~~~~~~~~~~~~~~~^^^^^^^^^^^^^^^^^^^^^^^^^^^^^^^^^^
UnicodeEncodeError: 'charmap' codec can't encode character '\U0001f389' in position 137: character maps to <undefined>
[13:51:05] Iniciando envio pela planilha...
[13:51] Avaliando envio para M„e (+5548999181410)...
     [HORA] Agora: 27/07/2025 13:51 | Agendado: 27/07/2025 13:48
[13:51] Enviando mensagem para M„e (+5548999181410)...
Traceback (most recent call last):
  File "C:\IMPAR\enviar_whatsapp.py", line 67, in main
    subprocess.run(["python", CAMINHO_SCRIPT_ENVIO, telefone, mensagem], check=True)
    ~~~~~~~~~~~~~~^^^^^^^^^^^^^^^^^^^^^^^^^^^^^^^^^^^^^^^^^^^^^^^^^^^^^^^^^^^^^^^^^^
  File "C:\Users\ramos\AppData\Local\Programs\Python\Python313\Lib\subprocess.py", line 577, in run
    raise CalledProcessError(retcode, process.args,
                             output=stdout, stderr=stderr)
subprocess.CalledProcessError: Command '['python', 'C:/IMPAR/enviar_whatsapp.py', '+5548999181410', 'Feliz anivers·rio, M„e! \U0001f389']' returned non-zero exit status 1.

During handling of the above exception, another exception occurred:

Traceback (most recent call last):
  File "C:\IMPAR\enviar_whatsapp.py", line 78, in <module>
    main()
    ~~~~^^
  File "C:\IMPAR\enviar_whatsapp.py", line 71, in main
    print(f"[ERRO] Erro ao enviar para {telefone}: {e}")
    ~~~~~^^^^^^^^^^^^^^^^^^^^^^^^^^^^^^^^^^^^^^^^^^^^^^^
  File "C:\Users\ramos\AppData\Local\Programs\Python\Python313\Lib\encodings\cp1252.py", line 19, in encode
    return codecs.charmap_encode(input,self.errors,encoding_table)[0]
           ~~~~~~~~~~~~~~~~~~~~~^^^^^^^^^^^^^^^^^^^^^^^^^^^^^^^^^^
UnicodeEncodeError: 'charmap' codec can't encode character '\U0001f389' in position 137: character maps to <undefined>
[13:51:03] Iniciando envio pela planilha...
[13:51] Avaliando envio para M„e (+5548999181410)...
     [HORA] Agora: 27/07/2025 13:51 | Agendado: 27/07/2025 13:48
[13:51] Enviando mensagem para M„e (+5548999181410)...
Traceback (most recent call last):
  File "C:\IMPAR\enviar_whatsapp.py", line 67, in main
    subprocess.run(["python", CAMINHO_SCRIPT_ENVIO, telefone, mensagem], check=True)
    ~~~~~~~~~~~~~~^^^^^^^^^^^^^^^^^^^^^^^^^^^^^^^^^^^^^^^^^^^^^^^^^^^^^^^^^^^^^^^^^^
  File "C:\Users\ramos\AppData\Local\Programs\Python\Python313\Lib\subprocess.py", line 577, in run
    raise CalledProcessError(retcode, process.args,
                             output=stdout, stderr=stderr)
subprocess.CalledProcessError: Command '['python', 'C:/IMPAR/enviar_whatsapp.py', '+5548999181410', 'Feliz anivers·rio, M„e! \U0001f389']' returned non-zero exit status 1.

During handling of the above exception, another exception occurred:

Traceback (most recent call last):
  File "C:\IMPAR\enviar_whatsapp.py", line 78, in <module>
    main()
    ~~~~^^
  File "C:\IMPAR\enviar_whatsapp.py", line 71, in main
    print(f"[ERRO] Erro ao enviar para {telefone}: {e}")
    ~~~~~^^^^^^^^^^^^^^^^^^^^^^^^^^^^^^^^^^^^^^^^^^^^^^^
  File "C:\Users\ramos\AppData\Local\Programs\Python\Python313\Lib\encodings\cp1252.py", line 19, in encode
    return codecs.charmap_encode(input,self.errors,encoding_table)[0]
           ~~~~~~~~~~~~~~~~~~~~~^^^^^^^^^^^^^^^^^^^^^^^^^^^^^^^^^^
UnicodeEncodeError: 'charmap' codec can't encode character '\U0001f389' in position 137: character maps to <undefined>
[13:51:03] Iniciando envio pela planilha...
[13:51] Avaliando envio para M„e (+5548999181410)...
     [HORA] Agora: 27/07/2025 13:51 | Agendado: 27/07/2025 13:48
[13:51] Enviando mensagem para M„e (+5548999181410)...
Traceback (most recent call last):
  File "C:\IMPAR\enviar_whatsapp.py", line 67, in main
    subprocess.run(["python", CAMINHO_SCRIPT_ENVIO, telefone, mensagem], check=True)
    ~~~~~~~~~~~~~~^^^^^^^^^^^^^^^^^^^^^^^^^^^^^^^^^^^^^^^^^^^^^^^^^^^^^^^^^^^^^^^^^^
  File "C:\Users\ramos\AppData\Local\Programs\Python\Python313\Lib\subprocess.py", line 577, in run
    raise CalledProcessError(retcode, process.args,
                             output=stdout, stderr=stderr)
subprocess.CalledProcessError: Command '['python', 'C:/IMPAR/enviar_whatsapp.py', '+5548999181410', 'Feliz anivers·rio, M„e! \U0001f389']' returned non-zero exit status 1.

During handling of the above exception, another exception occurred:

Traceback (most recent call last):
  File "C:\IMPAR\enviar_whatsapp.py", line 78, in <module>
    main()
    ~~~~^^
  File "C:\IMPAR\enviar_whatsapp.py", line 71, in main
    print(f"[ERRO] Erro ao enviar para {telefone}: {e}")
    ~~~~~^^^^^^^^^^^^^^^^^^^^^^^^^^^^^^^^^^^^^^^^^^^^^^^
  File "C:\Users\ramos\AppData\Local\Programs\Python\Python313\Lib\encodings\cp1252.py", line 19, in encode
    return codecs.charmap_encode(input,self.errors,encoding_table)[0]
           ~~~~~~~~~~~~~~~~~~~~~^^^^^^^^^^^^^^^^^^^^^^^^^^^^^^^^^^
UnicodeEncodeError: 'charmap' codec can't encode character '\U0001f389' in position 137: character maps to <undefined>
[13:51:02] Iniciando envio pela planilha...
[13:51] Avaliando envio para M„e (+5548999181410)...
     [HORA] Agora: 27/07/2025 13:51 | Agendado: 27/07/2025 13:48
[13:51] Enviando mensagem para M„e (+5548999181410)...
Traceback (most recent call last):
  File "C:\IMPAR\enviar_whatsapp.py", line 67, in main
    subprocess.run(["python", CAMINHO_SCRIPT_ENVIO, telefone, mensagem], check=True)
    ~~~~~~~~~~~~~~^^^^^^^^^^^^^^^^^^^^^^^^^^^^^^^^^^^^^^^^^^^^^^^^^^^^^^^^^^^^^^^^^^
  File "C:\Users\ramos\AppData\Local\Programs\Python\Python313\Lib\subprocess.py", line 577, in run
    raise CalledProcessError(retcode, process.args,
                             output=stdout, stderr=stderr)
subprocess.CalledProcessError: Command '['python', 'C:/IMPAR/enviar_whatsapp.py', '+5548999181410', 'Feliz anivers·rio, M„e! \U0001f389']' returned non-zero exit status 1.

During handling of the above exception, another exception occurred:

Traceback (most recent call last):
  File "C:\IMPAR\enviar_whatsapp.py", line 78, in <module>
    main()
    ~~~~^^
  File "C:\IMPAR\enviar_whatsapp.py", line 71, in main
    print(f"[ERRO] Erro ao enviar para {telefone}: {e}")
    ~~~~~^^^^^^^^^^^^^^^^^^^^^^^^^^^^^^^^^^^^^^^^^^^^^^^
  File "C:\Users\ramos\AppData\Local\Programs\Python\Python313\Lib\encodings\cp1252.py", line 19, in encode
    return codecs.charmap_encode(input,self.errors,encoding_table)[0]
           ~~~~~~~~~~~~~~~~~~~~~^^^^^^^^^^^^^^^^^^^^^^^^^^^^^^^^^^
UnicodeEncodeError: 'charmap' codec can't encode character '\U0001f389' in position 137: character maps to <undefined>
[13:50:58] Iniciando envio pela planilha...
[13:50] Avaliando envio para M„e (+5548999181410)...
     [HORA] Agora: 27/07/2025 13:50 | Agendado: 27/07/2025 13:48
[13:50] Enviando mensagem para M„e (+5548999181410)...
Traceback (most recent call last):
  File "C:\IMPAR\enviar_whatsapp.py", line 67, in main
    subprocess.run(["python", CAMINHO_SCRIPT_ENVIO, telefone, mensagem], check=True)
    ~~~~~~~~~~~~~~^^^^^^^^^^^^^^^^^^^^^^^^^^^^^^^^^^^^^^^^^^^^^^^^^^^^^^^^^^^^^^^^^^
  File "C:\Users\ramos\AppData\Local\Programs\Python\Python313\Lib\subprocess.py", line 577, in run
    raise CalledProcessError(retcode, process.args,
                             output=stdout, stderr=stderr)
subprocess.CalledProcessError: Command '['python', 'C:/IMPAR/enviar_whatsapp.py', '+5548999181410', 'Feliz anivers·rio, M„e! \U0001f389']' returned non-zero exit status 1.

During handling of the above exception, another exception occurred:

Traceback (most recent call last):
  File "C:\IMPAR\enviar_whatsapp.py", line 78, in <module>
    main()
    ~~~~^^
  File "C:\IMPAR\enviar_whatsapp.py", line 71, in main
    print(f"[ERRO] Erro ao enviar para {telefone}: {e}")
    ~~~~~^^^^^^^^^^^^^^^^^^^^^^^^^^^^^^^^^^^^^^^^^^^^^^^
  File "C:\Users\ramos\AppData\Local\Programs\Python\Python313\Lib\encodings\cp1252.py", line 19, in encode
    return codecs.charmap_encode(input,self.errors,encoding_table)[0]
           ~~~~~~~~~~~~~~~~~~~~~^^^^^^^^^^^^^^^^^^^^^^^^^^^^^^^^^^
UnicodeEncodeError: 'charmap' codec can't encode character '\U0001f389' in position 137: character maps to <undefined>
[13:50:57] Iniciando envio pela planilha...
[13:50] Avaliando envio para M„e (+5548999181410)...
     [HORA] Agora: 27/07/2025 13:50 | Agendado: 27/07/2025 13:48
[13:50] Enviando mensagem para M„e (+5548999181410)...
Traceback (most recent call last):
  File "C:\IMPAR\enviar_whatsapp.py", line 67, in main
    subprocess.run(["python", CAMINHO_SCRIPT_ENVIO, telefone, mensagem], check=True)
    ~~~~~~~~~~~~~~^^^^^^^^^^^^^^^^^^^^^^^^^^^^^^^^^^^^^^^^^^^^^^^^^^^^^^^^^^^^^^^^^^
  File "C:\Users\ramos\AppData\Local\Programs\Python\Python313\Lib\subprocess.py", line 577, in run
    raise CalledProcessError(retcode, process.args,
                             output=stdout, stderr=stderr)
subprocess.CalledProcessError: Command '['python', 'C:/IMPAR/enviar_whatsapp.py', '+5548999181410', 'Feliz anivers·rio, M„e! \U0001f389']' returned non-zero exit status 1.

During handling of the above exception, another exception occurred:

Traceback (most recent call last):
  File "C:\IMPAR\enviar_whatsapp.py", line 78, in <module>
    main()
    ~~~~^^
  File "C:\IMPAR\enviar_whatsapp.py", line 71, in main
    print(f"[ERRO] Erro ao enviar para {telefone}: {e}")
    ~~~~~^^^^^^^^^^^^^^^^^^^^^^^^^^^^^^^^^^^^^^^^^^^^^^^
  File "C:\Users\ramos\AppData\Local\Programs\Python\Python313\Lib\encodings\cp1252.py", line 19, in encode
    return codecs.charmap_encode(input,self.errors,encoding_table)[0]
           ~~~~~~~~~~~~~~~~~~~~~^^^^^^^^^^^^^^^^^^^^^^^^^^^^^^^^^^
UnicodeEncodeError: 'charmap' codec can't encode character '\U0001f389' in position 137: character maps to <undefined>
[13:50:56] Iniciando envio pela planilha...
[13:50] Avaliando envio para M„e (+5548999181410)...
     [HORA] Agora: 27/07/2025 13:50 | Agendado: 27/07/2025 13:48
[13:50] Enviando mensagem para M„e (+5548999181410)...
Traceback (most recent call last):
  File "C:\IMPAR\enviar_whatsapp.py", line 67, in main
    subprocess.run(["python", CAMINHO_SCRIPT_ENVIO, telefone, mensagem], check=True)
    ~~~~~~~~~~~~~~^^^^^^^^^^^^^^^^^^^^^^^^^^^^^^^^^^^^^^^^^^^^^^^^^^^^^^^^^^^^^^^^^^
  File "C:\Users\ramos\AppData\Local\Programs\Python\Python313\Lib\subprocess.py", line 577, in run
    raise CalledProcessError(retcode, process.args,
                             output=stdout, stderr=stderr)
subprocess.CalledProcessError: Command '['python', 'C:/IMPAR/enviar_whatsapp.py', '+5548999181410', 'Feliz anivers·rio, M„e! \U0001f389']' returned non-zero exit status 1.

During handling of the above exception, another exception occurred:

Traceback (most recent call last):
  File "C:\IMPAR\enviar_whatsapp.py", line 78, in <module>
    main()
    ~~~~^^
  File "C:\IMPAR\enviar_whatsapp.py", line 71, in main
    print(f"[ERRO] Erro ao enviar para {telefone}: {e}")
    ~~~~~^^^^^^^^^^^^^^^^^^^^^^^^^^^^^^^^^^^^^^^^^^^^^^^
  File "C:\Users\ramos\AppData\Local\Programs\Python\Python313\Lib\encodings\cp1252.py", line 19, in encode
    return codecs.charmap_encode(input,self.errors,encoding_table)[0]
           ~~~~~~~~~~~~~~~~~~~~~^^^^^^^^^^^^^^^^^^^^^^^^^^^^^^^^^^
UnicodeEncodeError: 'charmap' codec can't encode character '\U0001f389' in position 137: character maps to <undefined>
[13:50:55] Iniciando envio pela planilha...
[13:50] Avaliando envio para M„e (+5548999181410)...
     [HORA] Agora: 27/07/2025 13:50 | Agendado: 27/07/2025 13:48
[13:50] Enviando mensagem para M„e (+5548999181410)...
Traceback (most recent call last):
  File "C:\IMPAR\enviar_whatsapp.py", line 67, in main
    subprocess.run(["python", CAMINHO_SCRIPT_ENVIO, telefone, mensagem], check=True)
    ~~~~~~~~~~~~~~^^^^^^^^^^^^^^^^^^^^^^^^^^^^^^^^^^^^^^^^^^^^^^^^^^^^^^^^^^^^^^^^^^
  File "C:\Users\ramos\AppData\Local\Programs\Python\Python313\Lib\subprocess.py", line 577, in run
    raise CalledProcessError(retcode, process.args,
                             output=stdout, stderr=stderr)
subprocess.CalledProcessError: Command '['python', 'C:/IMPAR/enviar_whatsapp.py', '+5548999181410', 'Feliz anivers·rio, M„e! \U0001f389']' returned non-zero exit status 1.

During handling of the above exception, another exception occurred:

Traceback (most recent call last):
  File "C:\IMPAR\enviar_whatsapp.py", line 78, in <module>
    main()
    ~~~~^^
  File "C:\IMPAR\enviar_whatsapp.py", line 71, in main
    print(f"[ERRO] Erro ao enviar para {telefone}: {e}")
    ~~~~~^^^^^^^^^^^^^^^^^^^^^^^^^^^^^^^^^^^^^^^^^^^^^^^
  File "C:\Users\ramos\AppData\Local\Programs\Python\Python313\Lib\encodings\cp1252.py", line 19, in encode
    return codecs.charmap_encode(input,self.errors,encoding_table)[0]
           ~~~~~~~~~~~~~~~~~~~~~^^^^^^^^^^^^^^^^^^^^^^^^^^^^^^^^^^
UnicodeEncodeError: 'charmap' codec can't encode character '\U0001f389' in position 137: character maps to <undefined>
[13:50:53] Iniciando envio pela planilha...
[13:50] Avaliando envio para M„e (+5548999181410)...
     [HORA] Agora: 27/07/2025 13:50 | Agendado: 27/07/2025 13:48
[13:50] Enviando mensagem para M„e (+5548999181410)...
Traceback (most recent call last):
  File "C:\IMPAR\enviar_whatsapp.py", line 67, in main
    subprocess.run(["python", CAMINHO_SCRIPT_ENVIO, telefone, mensagem], check=True)
    ~~~~~~~~~~~~~~^^^^^^^^^^^^^^^^^^^^^^^^^^^^^^^^^^^^^^^^^^^^^^^^^^^^^^^^^^^^^^^^^^
  File "C:\Users\ramos\AppData\Local\Programs\Python\Python313\Lib\subprocess.py", line 577, in run
    raise CalledProcessError(retcode, process.args,
                             output=stdout, stderr=stderr)
subprocess.CalledProcessError: Command '['python', 'C:/IMPAR/enviar_whatsapp.py', '+5548999181410', 'Feliz anivers·rio, M„e! \U0001f389']' returned non-zero exit status 1.

During handling of the above exception, another exception occurred:

Traceback (most recent call last):
  File "C:\IMPAR\enviar_whatsapp.py", line 78, in <module>
    main()
    ~~~~^^
  File "C:\IMPAR\enviar_whatsapp.py", line 71, in main
    print(f"[ERRO] Erro ao enviar para {telefone}: {e}")
    ~~~~~^^^^^^^^^^^^^^^^^^^^^^^^^^^^^^^^^^^^^^^^^^^^^^^
  File "C:\Users\ramos\AppData\Local\Programs\Python\Python313\Lib\encodings\cp1252.py", line 19, in encode
    return codecs.charmap_encode(input,self.errors,encoding_table)[0]
           ~~~~~~~~~~~~~~~~~~~~~^^^^^^^^^^^^^^^^^^^^^^^^^^^^^^^^^^
UnicodeEncodeError: 'charmap' codec can't encode character '\U0001f389' in position 137: character maps to <undefined>
[13:50:52] Iniciando envio pela planilha...
[13:50] Avaliando envio para M„e (+5548999181410)...
     [HORA] Agora: 27/07/2025 13:50 | Agendado: 27/07/2025 13:48
[13:50] Enviando mensagem para M„e (+5548999181410)...
Traceback (most recent call last):
  File "C:\IMPAR\enviar_whatsapp.py", line 67, in main
    subprocess.run(["python", CAMINHO_SCRIPT_ENVIO, telefone, mensagem], check=True)
    ~~~~~~~~~~~~~~^^^^^^^^^^^^^^^^^^^^^^^^^^^^^^^^^^^^^^^^^^^^^^^^^^^^^^^^^^^^^^^^^^
  File "C:\Users\ramos\AppData\Local\Programs\Python\Python313\Lib\subprocess.py", line 577, in run
    raise CalledProcessError(retcode, process.args,
                             output=stdout, stderr=stderr)
subprocess.CalledProcessError: Command '['python', 'C:/IMPAR/enviar_whatsapp.py', '+5548999181410', 'Feliz anivers·rio, M„e! \U0001f389']' returned non-zero exit status 1.

During handling of the above exception, another exception occurred:

Traceback (most recent call last):
  File "C:\IMPAR\enviar_whatsapp.py", line 78, in <module>
    main()
    ~~~~^^
  File "C:\IMPAR\enviar_whatsapp.py", line 71, in main
    print(f"[ERRO] Erro ao enviar para {telefone}: {e}")
    ~~~~~^^^^^^^^^^^^^^^^^^^^^^^^^^^^^^^^^^^^^^^^^^^^^^^
  File "C:\Users\ramos\AppData\Local\Programs\Python\Python313\Lib\encodings\cp1252.py", line 19, in encode
    return codecs.charmap_encode(input,self.errors,encoding_table)[0]
           ~~~~~~~~~~~~~~~~~~~~~^^^^^^^^^^^^^^^^^^^^^^^^^^^^^^^^^^
UnicodeEncodeError: 'charmap' codec can't encode character '\U0001f389' in position 137: character maps to <undefined>
[13:50:51] Iniciando envio pela planilha...
[13:50] Avaliando envio para M„e (+5548999181410)...
     [HORA] Agora: 27/07/2025 13:50 | Agendado: 27/07/2025 13:48
[13:50] Enviando mensagem para M„e (+5548999181410)...
Traceback (most recent call last):
  File "C:\IMPAR\enviar_todos.py", line 67, in main
    subprocess.run(["python", CAMINHO_SCRIPT_ENVIO, telefone, mensagem], check=True)
    ~~~~~~~~~~~~~~^^^^^^^^^^^^^^^^^^^^^^^^^^^^^^^^^^^^^^^^^^^^^^^^^^^^^^^^^^^^^^^^^^
  File "C:\Users\ramos\AppData\Local\Programs\Python\Python313\Lib\subprocess.py", line 577, in run
    raise CalledProcessError(retcode, process.args,
                             output=stdout, stderr=stderr)
subprocess.CalledProcessError: Command '['python', 'C:/IMPAR/enviar_whatsapp.py', '+5548999181410', 'Feliz anivers·rio, M„e! \U0001f389']' returned non-zero exit status 1.

During handling of the above exception, another exception occurred:

Traceback (most recent call last):
  File "C:\IMPAR\enviar_todos.py", line 78, in <module>
    main()
    ~~~~^^
  File "C:\IMPAR\enviar_todos.py", line 71, in main
    print(f"[ERRO] Erro ao enviar para {telefone}: {e}")
    ~~~~~^^^^^^^^^^^^^^^^^^^^^^^^^^^^^^^^^^^^^^^^^^^^^^^
  File "C:\Users\ramos\AppData\Local\Programs\Python\Python313\Lib\encodings\cp1252.py", line 19, in encode
    return codecs.charmap_encode(input,self.errors,encoding_table)[0]
           ~~~~~~~~~~~~~~~~~~~~~^^^^^^^^^^^^^^^^^^^^^^^^^^^^^^^^^^
UnicodeEncodeError: 'charmap' codec can't encode character '\U0001f389' in position 137: character maps to <undefined>
[FIM] 27/07/2025 13:59:09,70 
 
